ply
format ascii 1.0
comment : MagicaVoxel @ Ephtracy
element vertex 32832
property float x
property float y
property float z
property uchar red
property uchar green
property uchar blue
end_header
-48 -39 -9 178 197 83
-47 -39 -9 178 197 83
-46 -39 -9 178 197 83
-45 -39 -9 178 197 83
-44 -39 -9 178 197 83
-43 -39 -9 178 197 83
-42 -39 -9 178 197 83
-41 -39 -9 178 197 83
-40 -39 -9 178 197 83
-39 -39 -9 178 197 83
-38 -39 -9 178 197 83
-37 -39 -9 178 197 83
-36 -39 -9 178 197 83
-35 -39 -9 178 197 83
-34 -39 -9 178 197 83
-33 -39 -9 178 197 83
-32 -39 -9 178 197 83
-31 -39 -9 178 197 83
-30 -39 -9 178 197 83
-29 -39 -9 178 197 83
-28 -39 -9 178 197 83
-27 -39 -9 178 197 83
-26 -39 -9 178 197 83
-25 -39 -9 178 197 83
-24 -39 -9 178 197 83
-23 -39 -9 178 197 83
-22 -39 -9 178 197 83
-21 -39 -9 178 197 83
-20 -39 -9 178 197 83
-19 -39 -9 178 197 83
-18 -39 -9 178 197 83
-17 -39 -9 178 197 83
-16 -39 -9 178 197 83
-15 -39 -9 178 197 83
-14 -39 -9 178 197 83
-13 -39 -9 178 197 83
-12 -39 -9 178 197 83
-11 -39 -9 178 197 83
-10 -39 -9 178 197 83
-9 -39 -9 178 197 83
-8 -39 -9 178 197 83
-7 -39 -9 178 197 83
-6 -39 -9 178 197 83
-5 -39 -9 178 197 83
-4 -39 -9 178 197 83
-3 -39 -9 178 197 83
-2 -39 -9 178 197 83
-1 -39 -9 178 197 83
0 -39 -9 178 197 83
1 -39 -9 178 197 83
2 -39 -9 178 197 83
3 -39 -9 178 197 83
4 -39 -9 178 197 83
5 -39 -9 178 197 83
6 -39 -9 178 197 83
7 -39 -9 178 197 83
8 -39 -9 178 197 83
9 -39 -9 178 197 83
10 -39 -9 178 197 83
11 -39 -9 178 197 83
12 -39 -9 178 197 83
13 -39 -9 178 197 83
14 -39 -9 178 197 83
15 -39 -9 178 197 83
16 -39 -9 178 197 83
17 -39 -9 178 197 83
18 -39 -9 178 197 83
19 -39 -9 178 197 83
20 -39 -9 178 197 83
21 -39 -9 178 197 83
22 -39 -9 178 197 83
23 -39 -9 178 197 83
24 -39 -9 178 197 83
25 -39 -9 178 197 83
26 -39 -9 178 197 83
27 -39 -9 178 197 83
28 -39 -9 178 197 83
29 -39 -9 178 197 83
30 -39 -9 178 197 83
31 -39 -9 178 197 83
32 -39 -9 178 197 83
33 -39 -9 178 197 83
34 -39 -9 178 197 83
35 -39 -9 178 197 83
36 -39 -9 178 197 83
37 -39 -9 178 197 83
38 -39 -9 178 197 83
39 -39 -9 178 197 83
40 -39 -9 178 197 83
41 -39 -9 178 197 83
42 -39 -9 178 197 83
43 -39 -9 178 197 83
44 -39 -9 178 197 83
45 -39 -9 178 197 83
46 -39 -9 178 197 83
47 -39 -9 178 197 83
48 -39 -9 178 197 83
-48 -39 -8 178 197 83
-47 -39 -8 178 197 83
-46 -39 -8 178 197 83
-45 -39 -8 178 197 83
-44 -39 -8 178 197 83
-43 -39 -8 178 197 83
-42 -39 -8 178 197 83
-41 -39 -8 178 197 83
-40 -39 -8 178 197 83
-39 -39 -8 178 197 83
-38 -39 -8 178 197 83
-37 -39 -8 178 197 83
-36 -39 -8 178 197 83
-35 -39 -8 178 197 83
-34 -39 -8 178 197 83
-33 -39 -8 178 197 83
-32 -39 -8 178 197 83
-31 -39 -8 178 197 83
-30 -39 -8 178 197 83
-29 -39 -8 178 197 83
-28 -39 -8 178 197 83
-27 -39 -8 178 197 83
-26 -39 -8 178 197 83
-25 -39 -8 178 197 83
-24 -39 -8 178 197 83
-23 -39 -8 178 197 83
-22 -39 -8 178 197 83
-21 -39 -8 178 197 83
-20 -39 -8 178 197 83
-19 -39 -8 178 197 83
-18 -39 -8 178 197 83
-17 -39 -8 178 197 83
-16 -39 -8 178 197 83
-15 -39 -8 178 197 83
-14 -39 -8 178 197 83
-13 -39 -8 178 197 83
-12 -39 -8 178 197 83
-11 -39 -8 178 197 83
-10 -39 -8 178 197 83
-9 -39 -8 178 197 83
-8 -39 -8 178 197 83
-7 -39 -8 178 197 83
-6 -39 -8 178 197 83
-5 -39 -8 178 197 83
-4 -39 -8 178 197 83
-3 -39 -8 178 197 83
-2 -39 -8 178 197 83
-1 -39 -8 178 197 83
0 -39 -8 178 197 83
1 -39 -8 178 197 83
2 -39 -8 178 197 83
3 -39 -8 178 197 83
4 -39 -8 178 197 83
5 -39 -8 178 197 83
6 -39 -8 178 197 83
7 -39 -8 178 197 83
8 -39 -8 178 197 83
9 -39 -8 178 197 83
10 -39 -8 178 197 83
11 -39 -8 178 197 83
12 -39 -8 178 197 83
13 -39 -8 178 197 83
14 -39 -8 178 197 83
15 -39 -8 178 197 83
16 -39 -8 178 197 83
17 -39 -8 178 197 83
18 -39 -8 178 197 83
19 -39 -8 178 197 83
20 -39 -8 178 197 83
21 -39 -8 178 197 83
22 -39 -8 178 197 83
23 -39 -8 178 197 83
24 -39 -8 178 197 83
25 -39 -8 178 197 83
26 -39 -8 178 197 83
27 -39 -8 178 197 83
28 -39 -8 178 197 83
29 -39 -8 178 197 83
30 -39 -8 178 197 83
31 -39 -8 178 197 83
32 -39 -8 178 197 83
33 -39 -8 178 197 83
34 -39 -8 178 197 83
35 -39 -8 178 197 83
36 -39 -8 178 197 83
37 -39 -8 178 197 83
38 -39 -8 178 197 83
39 -39 -8 178 197 83
40 -39 -8 178 197 83
41 -39 -8 178 197 83
42 -39 -8 178 197 83
43 -39 -8 178 197 83
44 -39 -8 178 197 83
45 -39 -8 178 197 83
46 -39 -8 178 197 83
47 -39 -8 178 197 83
48 -39 -8 178 197 83
-48 -39 -7 178 197 83
-47 -39 -7 178 197 83
-46 -39 -7 178 197 83
-45 -39 -7 178 197 83
-44 -39 -7 178 197 83
-43 -39 -7 178 197 83
-42 -39 -7 178 197 83
-41 -39 -7 178 197 83
-40 -39 -7 178 197 83
-39 -39 -7 178 197 83
-38 -39 -7 178 197 83
-37 -39 -7 178 197 83
-36 -39 -7 178 197 83
-35 -39 -7 178 197 83
-34 -39 -7 178 197 83
-33 -39 -7 178 197 83
-32 -39 -7 178 197 83
-31 -39 -7 178 197 83
-30 -39 -7 178 197 83
-29 -39 -7 178 197 83
-28 -39 -7 178 197 83
-27 -39 -7 178 197 83
-26 -39 -7 178 197 83
-25 -39 -7 178 197 83
-24 -39 -7 178 197 83
-23 -39 -7 178 197 83
-22 -39 -7 178 197 83
-21 -39 -7 178 197 83
-20 -39 -7 178 197 83
-19 -39 -7 178 197 83
-18 -39 -7 178 197 83
-17 -39 -7 178 197 83
-16 -39 -7 178 197 83
-15 -39 -7 178 197 83
-14 -39 -7 178 197 83
-13 -39 -7 178 197 83
-12 -39 -7 178 197 83
-11 -39 -7 178 197 83
-10 -39 -7 178 197 83
-9 -39 -7 178 197 83
-8 -39 -7 178 197 83
-7 -39 -7 178 197 83
-6 -39 -7 178 197 83
-5 -39 -7 178 197 83
-4 -39 -7 178 197 83
-3 -39 -7 178 197 83
-2 -39 -7 178 197 83
-1 -39 -7 178 197 83
0 -39 -7 178 197 83
1 -39 -7 178 197 83
2 -39 -7 178 197 83
3 -39 -7 178 197 83
4 -39 -7 178 197 83
5 -39 -7 178 197 83
6 -39 -7 178 197 83
7 -39 -7 178 197 83
8 -39 -7 178 197 83
9 -39 -7 178 197 83
10 -39 -7 178 197 83
11 -39 -7 178 197 83
12 -39 -7 178 197 83
13 -39 -7 178 197 83
14 -39 -7 178 197 83
15 -39 -7 178 197 83
16 -39 -7 178 197 83
17 -39 -7 178 197 83
18 -39 -7 178 197 83
19 -39 -7 178 197 83
20 -39 -7 178 197 83
21 -39 -7 178 197 83
22 -39 -7 178 197 83
23 -39 -7 178 197 83
24 -39 -7 178 197 83
25 -39 -7 178 197 83
26 -39 -7 178 197 83
27 -39 -7 178 197 83
28 -39 -7 178 197 83
29 -39 -7 178 197 83
30 -39 -7 178 197 83
31 -39 -7 178 197 83
32 -39 -7 178 197 83
33 -39 -7 178 197 83
34 -39 -7 178 197 83
35 -39 -7 178 197 83
36 -39 -7 178 197 83
37 -39 -7 178 197 83
38 -39 -7 178 197 83
39 -39 -7 178 197 83
40 -39 -7 178 197 83
41 -39 -7 178 197 83
42 -39 -7 178 197 83
43 -39 -7 178 197 83
44 -39 -7 178 197 83
45 -39 -7 178 197 83
46 -39 -7 178 197 83
47 -39 -7 178 197 83
48 -39 -7 178 197 83
-48 -39 -6 178 197 83
-47 -39 -6 178 197 83
-46 -39 -6 178 197 83
-45 -39 -6 178 197 83
-44 -39 -6 178 197 83
-43 -39 -6 178 197 83
-42 -39 -6 178 197 83
-41 -39 -6 178 197 83
-40 -39 -6 178 197 83
-39 -39 -6 178 197 83
-38 -39 -6 178 197 83
-37 -39 -6 178 197 83
-36 -39 -6 178 197 83
-35 -39 -6 178 197 83
-34 -39 -6 178 197 83
-33 -39 -6 178 197 83
-32 -39 -6 178 197 83
-31 -39 -6 178 197 83
-30 -39 -6 178 197 83
-29 -39 -6 178 197 83
-28 -39 -6 178 197 83
-27 -39 -6 178 197 83
-26 -39 -6 178 197 83
-25 -39 -6 178 197 83
-24 -39 -6 178 197 83
-23 -39 -6 178 197 83
-22 -39 -6 178 197 83
-21 -39 -6 178 197 83
-20 -39 -6 178 197 83
-19 -39 -6 178 197 83
-18 -39 -6 178 197 83
-17 -39 -6 178 197 83
-16 -39 -6 178 197 83
-15 -39 -6 178 197 83
-14 -39 -6 178 197 83
-13 -39 -6 178 197 83
-12 -39 -6 178 197 83
-11 -39 -6 178 197 83
-10 -39 -6 178 197 83
-9 -39 -6 178 197 83
-8 -39 -6 178 197 83
-7 -39 -6 178 197 83
-6 -39 -6 178 197 83
-5 -39 -6 178 197 83
-4 -39 -6 178 197 83
-3 -39 -6 178 197 83
-2 -39 -6 178 197 83
-1 -39 -6 178 197 83
0 -39 -6 178 197 83
1 -39 -6 178 197 83
2 -39 -6 178 197 83
3 -39 -6 178 197 83
4 -39 -6 178 197 83
5 -39 -6 178 197 83
6 -39 -6 178 197 83
7 -39 -6 178 197 83
8 -39 -6 178 197 83
9 -39 -6 178 197 83
10 -39 -6 178 197 83
11 -39 -6 178 197 83
12 -39 -6 178 197 83
13 -39 -6 178 197 83
14 -39 -6 178 197 83
15 -39 -6 178 197 83
16 -39 -6 178 197 83
17 -39 -6 178 197 83
18 -39 -6 178 197 83
19 -39 -6 178 197 83
20 -39 -6 178 197 83
21 -39 -6 178 197 83
22 -39 -6 178 197 83
23 -39 -6 178 197 83
24 -39 -6 178 197 83
25 -39 -6 178 197 83
26 -39 -6 178 197 83
27 -39 -6 178 197 83
28 -39 -6 178 197 83
29 -39 -6 178 197 83
30 -39 -6 178 197 83
31 -39 -6 178 197 83
32 -39 -6 178 197 83
33 -39 -6 178 197 83
34 -39 -6 178 197 83
35 -39 -6 178 197 83
36 -39 -6 178 197 83
37 -39 -6 178 197 83
38 -39 -6 178 197 83
39 -39 -6 178 197 83
40 -39 -6 178 197 83
41 -39 -6 178 197 83
42 -39 -6 178 197 83
43 -39 -6 178 197 83
44 -39 -6 178 197 83
45 -39 -6 178 197 83
46 -39 -6 178 197 83
47 -39 -6 178 197 83
48 -39 -6 178 197 83
12 -37 -6 255 255 255
-48 -39 -5 178 197 83
-47 -39 -5 178 197 83
-46 -39 -5 178 197 83
-45 -39 -5 178 197 83
-44 -39 -5 178 197 83
-43 -39 -5 178 197 83
-42 -39 -5 178 197 83
-41 -39 -5 178 197 83
-40 -39 -5 178 197 83
-39 -39 -5 178 197 83
-38 -39 -5 178 197 83
-37 -39 -5 178 197 83
-36 -39 -5 178 197 83
-35 -39 -5 178 197 83
-34 -39 -5 178 197 83
-33 -39 -5 178 197 83
-32 -39 -5 178 197 83
-31 -39 -5 178 197 83
-30 -39 -5 178 197 83
-29 -39 -5 178 197 83
-28 -39 -5 178 197 83
-27 -39 -5 178 197 83
-26 -39 -5 178 197 83
-25 -39 -5 178 197 83
-24 -39 -5 178 197 83
-23 -39 -5 178 197 83
-22 -39 -5 178 197 83
-21 -39 -5 178 197 83
-20 -39 -5 178 197 83
-19 -39 -5 178 197 83
-18 -39 -5 178 197 83
-17 -39 -5 178 197 83
-16 -39 -5 178 197 83
-15 -39 -5 178 197 83
-14 -39 -5 178 197 83
-13 -39 -5 178 197 83
-12 -39 -5 178 197 83
-11 -39 -5 178 197 83
-10 -39 -5 178 197 83
-9 -39 -5 178 197 83
-8 -39 -5 178 197 83
-7 -39 -5 178 197 83
-6 -39 -5 178 197 83
-5 -39 -5 178 197 83
-4 -39 -5 178 197 83
-3 -39 -5 178 197 83
-2 -39 -5 178 197 83
-1 -39 -5 178 197 83
0 -39 -5 178 197 83
1 -39 -5 178 197 83
2 -39 -5 178 197 83
3 -39 -5 178 197 83
4 -39 -5 178 197 83
5 -39 -5 178 197 83
6 -39 -5 178 197 83
7 -39 -5 178 197 83
8 -39 -5 178 197 83
9 -39 -5 178 197 83
10 -39 -5 178 197 83
11 -39 -5 178 197 83
12 -39 -5 178 197 83
13 -39 -5 178 197 83
14 -39 -5 178 197 83
15 -39 -5 178 197 83
16 -39 -5 178 197 83
17 -39 -5 178 197 83
18 -39 -5 178 197 83
19 -39 -5 178 197 83
20 -39 -5 178 197 83
21 -39 -5 178 197 83
22 -39 -5 178 197 83
23 -39 -5 178 197 83
24 -39 -5 178 197 83
25 -39 -5 178 197 83
26 -39 -5 178 197 83
27 -39 -5 178 197 83
28 -39 -5 178 197 83
29 -39 -5 178 197 83
30 -39 -5 178 197 83
31 -39 -5 178 197 83
32 -39 -5 178 197 83
33 -39 -5 178 197 83
34 -39 -5 178 197 83
35 -39 -5 178 197 83
36 -39 -5 178 197 83
37 -39 -5 178 197 83
38 -39 -5 178 197 83
39 -39 -5 178 197 83
40 -39 -5 178 197 83
41 -39 -5 178 197 83
42 -39 -5 178 197 83
43 -39 -5 178 197 83
44 -39 -5 178 197 83
45 -39 -5 178 197 83
46 -39 -5 178 197 83
47 -39 -5 178 197 83
48 -39 -5 178 197 83
-41 -38 -5 103 113 88
-40 -38 -5 103 113 88
-39 -38 -5 103 113 88
12 -38 -5 255 255 255
-41 -37 -5 103 113 88
-40 -37 -5 103 113 88
-39 -37 -5 103 113 88
11 -37 -5 255 255 255
12 -37 -5 255 255 255
13 -37 -5 255 255 255
-41 -36 -5 103 113 88
-40 -36 -5 103 113 88
-39 -36 -5 103 113 88
-41 -35 -5 103 113 88
-40 -35 -5 103 113 88
-39 -35 -5 103 113 88
-41 -34 -5 103 113 88
-40 -34 -5 103 113 88
-39 -34 -5 103 113 88
-48 -39 -4 178 197 83
-47 -39 -4 178 197 83
-46 -39 -4 178 197 83
-45 -39 -4 178 197 83
-44 -39 -4 178 197 83
-43 -39 -4 178 197 83
-42 -39 -4 178 197 83
-41 -39 -4 178 197 83
-40 -39 -4 178 197 83
-39 -39 -4 178 197 83
-38 -39 -4 178 197 83
-37 -39 -4 178 197 83
-36 -39 -4 178 197 83
-35 -39 -4 178 197 83
-34 -39 -4 178 197 83
-33 -39 -4 178 197 83
-32 -39 -4 178 197 83
-31 -39 -4 178 197 83
-30 -39 -4 178 197 83
-29 -39 -4 178 197 83
-28 -39 -4 178 197 83
-27 -39 -4 178 197 83
-26 -39 -4 178 197 83
-25 -39 -4 178 197 83
-24 -39 -4 178 197 83
-23 -39 -4 178 197 83
-22 -39 -4 178 197 83
-21 -39 -4 178 197 83
-20 -39 -4 178 197 83
-19 -39 -4 178 197 83
-18 -39 -4 178 197 83
-17 -39 -4 178 197 83
-16 -39 -4 178 197 83
-15 -39 -4 178 197 83
-14 -39 -4 178 197 83
-13 -39 -4 178 197 83
-12 -39 -4 178 197 83
-11 -39 -4 178 197 83
-10 -39 -4 178 197 83
-9 -39 -4 178 197 83
-8 -39 -4 178 197 83
-7 -39 -4 178 197 83
-6 -39 -4 178 197 83
-5 -39 -4 178 197 83
-4 -39 -4 178 197 83
-3 -39 -4 178 197 83
-2 -39 -4 178 197 83
-1 -39 -4 178 197 83
0 -39 -4 178 197 83
1 -39 -4 178 197 83
2 -39 -4 178 197 83
3 -39 -4 178 197 83
4 -39 -4 178 197 83
5 -39 -4 178 197 83
6 -39 -4 178 197 83
7 -39 -4 178 197 83
8 -39 -4 178 197 83
9 -39 -4 178 197 83
10 -39 -4 178 197 83
11 -39 -4 178 197 83
12 -39 -4 178 197 83
13 -39 -4 178 197 83
14 -39 -4 178 197 83
15 -39 -4 178 197 83
16 -39 -4 178 197 83
17 -39 -4 178 197 83
18 -39 -4 178 197 83
19 -39 -4 178 197 83
20 -39 -4 178 197 83
21 -39 -4 178 197 83
22 -39 -4 178 197 83
23 -39 -4 178 197 83
24 -39 -4 178 197 83
25 -39 -4 178 197 83
26 -39 -4 178 197 83
27 -39 -4 178 197 83
28 -39 -4 178 197 83
29 -39 -4 178 197 83
30 -39 -4 178 197 83
31 -39 -4 178 197 83
32 -39 -4 178 197 83
33 -39 -4 178 197 83
34 -39 -4 178 197 83
35 -39 -4 178 197 83
36 -39 -4 178 197 83
37 -39 -4 178 197 83
38 -39 -4 178 197 83
39 -39 -4 178 197 83
40 -39 -4 178 197 83
41 -39 -4 178 197 83
42 -39 -4 178 197 83
43 -39 -4 178 197 83
44 -39 -4 178 197 83
45 -39 -4 178 197 83
46 -39 -4 178 197 83
47 -39 -4 178 197 83
48 -39 -4 178 197 83
-41 -38 -4 103 113 88
-40 -38 -4 103 113 88
-39 -38 -4 103 113 88
-41 -37 -4 103 113 88
-40 -37 -4 103 113 88
-39 -37 -4 103 113 88
12 -37 -4 255 255 255
-41 -36 -4 103 113 88
-40 -36 -4 103 113 88
-39 -36 -4 103 113 88
-41 -35 -4 103 113 88
-40 -35 -4 103 113 88
-39 -35 -4 103 113 88
-41 -34 -4 103 113 88
-40 -34 -4 103 113 88
-39 -34 -4 103 113 88
-48 -39 -3 178 197 83
-47 -39 -3 178 197 83
-46 -39 -3 178 197 83
-45 -39 -3 178 197 83
-44 -39 -3 178 197 83
-43 -39 -3 178 197 83
-42 -39 -3 178 197 83
-41 -39 -3 178 197 83
-40 -39 -3 178 197 83
-39 -39 -3 178 197 83
-38 -39 -3 178 197 83
-37 -39 -3 178 197 83
-36 -39 -3 178 197 83
-35 -39 -3 178 197 83
-34 -39 -3 178 197 83
-33 -39 -3 178 197 83
-32 -39 -3 178 197 83
-31 -39 -3 178 197 83
-30 -39 -3 178 197 83
-29 -39 -3 178 197 83
-28 -39 -3 178 197 83
-27 -39 -3 178 197 83
-26 -39 -3 178 197 83
-25 -39 -3 178 197 83
-24 -39 -3 178 197 83
-23 -39 -3 178 197 83
-22 -39 -3 178 197 83
-21 -39 -3 178 197 83
-20 -39 -3 178 197 83
-19 -39 -3 178 197 83
-18 -39 -3 178 197 83
-17 -39 -3 178 197 83
-16 -39 -3 178 197 83
-15 -39 -3 178 197 83
-14 -39 -3 178 197 83
-13 -39 -3 178 197 83
-12 -39 -3 178 197 83
-11 -39 -3 178 197 83
-10 -39 -3 178 197 83
-9 -39 -3 178 197 83
-8 -39 -3 178 197 83
-7 -39 -3 178 197 83
-6 -39 -3 178 197 83
-5 -39 -3 178 197 83
-4 -39 -3 178 197 83
-3 -39 -3 178 197 83
-2 -39 -3 178 197 83
-1 -39 -3 178 197 83
0 -39 -3 178 197 83
1 -39 -3 178 197 83
2 -39 -3 178 197 83
3 -39 -3 178 197 83
4 -39 -3 178 197 83
5 -39 -3 178 197 83
6 -39 -3 178 197 83
7 -39 -3 178 197 83
8 -39 -3 178 197 83
9 -39 -3 178 197 83
10 -39 -3 178 197 83
11 -39 -3 178 197 83
12 -39 -3 178 197 83
13 -39 -3 178 197 83
14 -39 -3 178 197 83
15 -39 -3 178 197 83
16 -39 -3 178 197 83
17 -39 -3 178 197 83
18 -39 -3 178 197 83
19 -39 -3 178 197 83
20 -39 -3 178 197 83
21 -39 -3 178 197 83
22 -39 -3 178 197 83
23 -39 -3 178 197 83
24 -39 -3 178 197 83
25 -39 -3 178 197 83
26 -39 -3 178 197 83
27 -39 -3 178 197 83
28 -39 -3 178 197 83
29 -39 -3 178 197 83
30 -39 -3 178 197 83
31 -39 -3 178 197 83
32 -39 -3 178 197 83
33 -39 -3 178 197 83
34 -39 -3 178 197 83
35 -39 -3 178 197 83
36 -39 -3 178 197 83
37 -39 -3 178 197 83
38 -39 -3 178 197 83
39 -39 -3 178 197 83
40 -39 -3 178 197 83
41 -39 -3 178 197 83
42 -39 -3 178 197 83
43 -39 -3 178 197 83
44 -39 -3 178 197 83
45 -39 -3 178 197 83
46 -39 -3 178 197 83
47 -39 -3 178 197 83
48 -39 -3 178 197 83
-41 -38 -3 103 113 88
-40 -38 -3 103 113 88
-39 -38 -3 103 113 88
-41 -37 -3 103 113 88
-40 -37 -3 103 113 88
-39 -37 -3 103 113 88
-28 -37 -3 255 255 255
-41 -36 -3 103 113 88
-40 -36 -3 103 113 88
-39 -36 -3 103 113 88
-41 -35 -3 103 113 88
-40 -35 -3 103 113 88
-39 -35 -3 103 113 88
-41 -34 -3 103 113 88
-40 -34 -3 103 113 88
-39 -34 -3 103 113 88
-48 -39 -2 178 197 83
-47 -39 -2 178 197 83
-46 -39 -2 178 197 83
-45 -39 -2 178 197 83
-44 -39 -2 178 197 83
-43 -39 -2 178 197 83
-42 -39 -2 178 197 83
-41 -39 -2 178 197 83
-40 -39 -2 178 197 83
-39 -39 -2 178 197 83
-38 -39 -2 178 197 83
-37 -39 -2 178 197 83
-36 -39 -2 178 197 83
-35 -39 -2 178 197 83
-34 -39 -2 178 197 83
-33 -39 -2 178 197 83
-32 -39 -2 178 197 83
-31 -39 -2 178 197 83
-30 -39 -2 178 197 83
-29 -39 -2 178 197 83
-28 -39 -2 178 197 83
-27 -39 -2 178 197 83
-26 -39 -2 178 197 83
-25 -39 -2 178 197 83
-24 -39 -2 178 197 83
-23 -39 -2 178 197 83
-22 -39 -2 178 197 83
-21 -39 -2 178 197 83
-20 -39 -2 178 197 83
-19 -39 -2 178 197 83
-18 -39 -2 178 197 83
-17 -39 -2 178 197 83
-16 -39 -2 178 197 83
-15 -39 -2 178 197 83
-14 -39 -2 178 197 83
-13 -39 -2 178 197 83
-12 -39 -2 178 197 83
-11 -39 -2 178 197 83
-10 -39 -2 178 197 83
-9 -39 -2 178 197 83
-8 -39 -2 178 197 83
-7 -39 -2 178 197 83
-6 -39 -2 178 197 83
-5 -39 -2 178 197 83
-4 -39 -2 178 197 83
-3 -39 -2 178 197 83
-2 -39 -2 178 197 83
-1 -39 -2 178 197 83
0 -39 -2 178 197 83
1 -39 -2 178 197 83
2 -39 -2 178 197 83
3 -39 -2 178 197 83
4 -39 -2 178 197 83
5 -39 -2 178 197 83
6 -39 -2 178 197 83
7 -39 -2 178 197 83
8 -39 -2 178 197 83
9 -39 -2 178 197 83
10 -39 -2 178 197 83
11 -39 -2 178 197 83
12 -39 -2 178 197 83
13 -39 -2 178 197 83
14 -39 -2 178 197 83
15 -39 -2 178 197 83
16 -39 -2 178 197 83
17 -39 -2 178 197 83
18 -39 -2 178 197 83
19 -39 -2 178 197 83
20 -39 -2 178 197 83
21 -39 -2 178 197 83
22 -39 -2 178 197 83
23 -39 -2 178 197 83
24 -39 -2 178 197 83
25 -39 -2 178 197 83
26 -39 -2 178 197 83
27 -39 -2 178 197 83
28 -39 -2 178 197 83
29 -39 -2 178 197 83
30 -39 -2 178 197 83
31 -39 -2 178 197 83
32 -39 -2 178 197 83
33 -39 -2 178 197 83
34 -39 -2 178 197 83
35 -39 -2 178 197 83
36 -39 -2 178 197 83
37 -39 -2 178 197 83
38 -39 -2 178 197 83
39 -39 -2 178 197 83
40 -39 -2 178 197 83
41 -39 -2 178 197 83
42 -39 -2 178 197 83
43 -39 -2 178 197 83
44 -39 -2 178 197 83
45 -39 -2 178 197 83
46 -39 -2 178 197 83
47 -39 -2 178 197 83
48 -39 -2 178 197 83
-28 -38 -2 255 255 255
6 -38 -2 103 113 88
7 -38 -2 103 113 88
8 -38 -2 103 113 88
-29 -37 -2 255 255 255
-28 -37 -2 255 255 255
-27 -37 -2 255 255 255
-1 -37 -2 255 255 255
6 -37 -2 103 113 88
7 -37 -2 103 113 88
8 -37 -2 103 113 88
21 -37 -2 255 255 255
6 -36 -2 103 113 88
7 -36 -2 103 113 88
8 -36 -2 103 113 88
-48 -39 -1 178 197 83
-47 -39 -1 178 197 83
-46 -39 -1 178 197 83
-45 -39 -1 178 197 83
-44 -39 -1 178 197 83
-43 -39 -1 178 197 83
-42 -39 -1 178 197 83
-41 -39 -1 178 197 83
-40 -39 -1 178 197 83
-39 -39 -1 178 197 83
-38 -39 -1 178 197 83
-37 -39 -1 178 197 83
-36 -39 -1 178 197 83
-35 -39 -1 178 197 83
-34 -39 -1 178 197 83
-33 -39 -1 178 197 83
-32 -39 -1 178 197 83
-31 -39 -1 178 197 83
-30 -39 -1 178 197 83
-29 -39 -1 178 197 83
-28 -39 -1 178 197 83
-27 -39 -1 178 197 83
-26 -39 -1 178 197 83
-25 -39 -1 178 197 83
-24 -39 -1 178 197 83
-23 -39 -1 178 197 83
-22 -39 -1 178 197 83
-21 -39 -1 178 197 83
-20 -39 -1 178 197 83
-19 -39 -1 178 197 83
-18 -39 -1 178 197 83
-17 -39 -1 178 197 83
-16 -39 -1 178 197 83
-15 -39 -1 178 197 83
-14 -39 -1 178 197 83
-13 -39 -1 178 197 83
-12 -39 -1 178 197 83
-11 -39 -1 178 197 83
-10 -39 -1 178 197 83
-9 -39 -1 178 197 83
-8 -39 -1 178 197 83
-7 -39 -1 178 197 83
-6 -39 -1 178 197 83
-5 -39 -1 178 197 83
-4 -39 -1 178 197 83
-3 -39 -1 178 197 83
-2 -39 -1 178 197 83
-1 -39 -1 178 197 83
0 -39 -1 178 197 83
1 -39 -1 178 197 83
2 -39 -1 178 197 83
3 -39 -1 178 197 83
4 -39 -1 178 197 83
5 -39 -1 178 197 83
6 -39 -1 178 197 83
7 -39 -1 178 197 83
8 -39 -1 178 197 83
9 -39 -1 178 197 83
10 -39 -1 178 197 83
11 -39 -1 178 197 83
12 -39 -1 178 197 83
13 -39 -1 178 197 83
14 -39 -1 178 197 83
15 -39 -1 178 197 83
16 -39 -1 178 197 83
17 -39 -1 178 197 83
18 -39 -1 178 197 83
19 -39 -1 178 197 83
20 -39 -1 178 197 83
21 -39 -1 178 197 83
22 -39 -1 178 197 83
23 -39 -1 178 197 83
24 -39 -1 178 197 83
25 -39 -1 178 197 83
26 -39 -1 178 197 83
27 -39 -1 178 197 83
28 -39 -1 178 197 83
29 -39 -1 178 197 83
30 -39 -1 178 197 83
31 -39 -1 178 197 83
32 -39 -1 178 197 83
33 -39 -1 178 197 83
34 -39 -1 178 197 83
35 -39 -1 178 197 83
36 -39 -1 178 197 83
37 -39 -1 178 197 83
38 -39 -1 178 197 83
39 -39 -1 178 197 83
40 -39 -1 178 197 83
41 -39 -1 178 197 83
42 -39 -1 178 197 83
43 -39 -1 178 197 83
44 -39 -1 178 197 83
45 -39 -1 178 197 83
46 -39 -1 178 197 83
47 -39 -1 178 197 83
48 -39 -1 178 197 83
-1 -38 -1 255 255 255
6 -38 -1 103 113 88
7 -38 -1 103 113 88
8 -38 -1 103 113 88
21 -38 -1 255 255 255
-28 -37 -1 255 255 255
-2 -37 -1 255 255 255
-1 -37 -1 255 255 255
0 -37 -1 255 255 255
6 -37 -1 103 113 88
7 -37 -1 103 113 88
8 -37 -1 103 113 88
20 -37 -1 255 255 255
21 -37 -1 255 255 255
22 -37 -1 255 255 255
6 -36 -1 103 113 88
7 -36 -1 103 113 88
8 -36 -1 103 113 88
-48 -39 0 178 197 83
-47 -39 0 178 197 83
-46 -39 0 178 197 83
-45 -39 0 178 197 83
-44 -39 0 178 197 83
-43 -39 0 178 197 83
-42 -39 0 178 197 83
-41 -39 0 178 197 83
-40 -39 0 178 197 83
-39 -39 0 178 197 83
-38 -39 0 178 197 83
-37 -39 0 178 197 83
-36 -39 0 178 197 83
-35 -39 0 178 197 83
-34 -39 0 178 197 83
-33 -39 0 178 197 83
-32 -39 0 178 197 83
-31 -39 0 178 197 83
-30 -39 0 178 197 83
-29 -39 0 178 197 83
-28 -39 0 178 197 83
-27 -39 0 178 197 83
-26 -39 0 178 197 83
-25 -39 0 178 197 83
-24 -39 0 178 197 83
-23 -39 0 178 197 83
-22 -39 0 178 197 83
-21 -39 0 178 197 83
-20 -39 0 178 197 83
-19 -39 0 178 197 83
-18 -39 0 178 197 83
-17 -39 0 178 197 83
-16 -39 0 178 197 83
-15 -39 0 178 197 83
-14 -39 0 178 197 83
-13 -39 0 178 197 83
-12 -39 0 178 197 83
-11 -39 0 178 197 83
-10 -39 0 178 197 83
-9 -39 0 178 197 83
-8 -39 0 178 197 83
-7 -39 0 178 197 83
-6 -39 0 178 197 83
-5 -39 0 178 197 83
-4 -39 0 178 197 83
-3 -39 0 178 197 83
-2 -39 0 178 197 83
-1 -39 0 178 197 83
0 -39 0 178 197 83
1 -39 0 178 197 83
2 -39 0 178 197 83
3 -39 0 178 197 83
4 -39 0 178 197 83
5 -39 0 178 197 83
6 -39 0 178 197 83
7 -39 0 178 197 83
8 -39 0 178 197 83
9 -39 0 178 197 83
10 -39 0 178 197 83
11 -39 0 178 197 83
12 -39 0 178 197 83
13 -39 0 178 197 83
14 -39 0 178 197 83
15 -39 0 178 197 83
16 -39 0 178 197 83
17 -39 0 178 197 83
18 -39 0 178 197 83
19 -39 0 178 197 83
20 -39 0 178 197 83
21 -39 0 178 197 83
22 -39 0 178 197 83
23 -39 0 178 197 83
24 -39 0 178 197 83
25 -39 0 178 197 83
26 -39 0 178 197 83
27 -39 0 178 197 83
28 -39 0 178 197 83
29 -39 0 178 197 83
30 -39 0 178 197 83
31 -39 0 178 197 83
32 -39 0 178 197 83
33 -39 0 178 197 83
34 -39 0 178 197 83
35 -39 0 178 197 83
36 -39 0 178 197 83
37 -39 0 178 197 83
38 -39 0 178 197 83
39 -39 0 178 197 83
40 -39 0 178 197 83
41 -39 0 178 197 83
42 -39 0 178 197 83
43 -39 0 178 197 83
44 -39 0 178 197 83
45 -39 0 178 197 83
46 -39 0 178 197 83
47 -39 0 178 197 83
48 -39 0 178 197 83
6 -38 0 103 113 88
7 -38 0 103 113 88
8 -38 0 103 113 88
31 -38 0 103 113 88
32 -38 0 103 113 88
33 -38 0 103 113 88
-1 -37 0 255 255 255
6 -37 0 103 113 88
7 -37 0 103 113 88
8 -37 0 103 113 88
21 -37 0 255 255 255
31 -37 0 103 113 88
32 -37 0 103 113 88
33 -37 0 103 113 88
6 -36 0 103 113 88
7 -36 0 103 113 88
8 -36 0 103 113 88
31 -36 0 103 113 88
32 -36 0 103 113 88
33 -36 0 103 113 88
-48 -39 1 178 197 83
-47 -39 1 178 197 83
-46 -39 1 178 197 83
-45 -39 1 178 197 83
-44 -39 1 178 197 83
-43 -39 1 178 197 83
-42 -39 1 178 197 83
-41 -39 1 178 197 83
-40 -39 1 178 197 83
-39 -39 1 178 197 83
-38 -39 1 178 197 83
-37 -39 1 178 197 83
-36 -39 1 178 197 83
-35 -39 1 178 197 83
-34 -39 1 178 197 83
-33 -39 1 178 197 83
-32 -39 1 178 197 83
-31 -39 1 178 197 83
-30 -39 1 178 197 83
-29 -39 1 178 197 83
-28 -39 1 178 197 83
-27 -39 1 178 197 83
-26 -39 1 178 197 83
-25 -39 1 178 197 83
-24 -39 1 178 197 83
-23 -39 1 178 197 83
-22 -39 1 178 197 83
-21 -39 1 178 197 83
-20 -39 1 178 197 83
-19 -39 1 178 197 83
-18 -39 1 178 197 83
-17 -39 1 178 197 83
-16 -39 1 178 197 83
-15 -39 1 178 197 83
-14 -39 1 178 197 83
-13 -39 1 178 197 83
-12 -39 1 178 197 83
-11 -39 1 178 197 83
-10 -39 1 178 197 83
-9 -39 1 178 197 83
-8 -39 1 178 197 83
-7 -39 1 178 197 83
-6 -39 1 178 197 83
-5 -39 1 178 197 83
-4 -39 1 178 197 83
-3 -39 1 178 197 83
-2 -39 1 178 197 83
-1 -39 1 178 197 83
0 -39 1 178 197 83
1 -39 1 178 197 83
2 -39 1 178 197 83
3 -39 1 178 197 83
4 -39 1 178 197 83
5 -39 1 178 197 83
6 -39 1 178 197 83
7 -39 1 178 197 83
8 -39 1 178 197 83
9 -39 1 178 197 83
10 -39 1 178 197 83
11 -39 1 178 197 83
12 -39 1 178 197 83
13 -39 1 178 197 83
14 -39 1 178 197 83
15 -39 1 178 197 83
16 -39 1 178 197 83
17 -39 1 178 197 83
18 -39 1 178 197 83
19 -39 1 178 197 83
20 -39 1 178 197 83
21 -39 1 178 197 83
22 -39 1 178 197 83
23 -39 1 178 197 83
24 -39 1 178 197 83
25 -39 1 178 197 83
26 -39 1 178 197 83
27 -39 1 178 197 83
28 -39 1 178 197 83
29 -39 1 178 197 83
30 -39 1 178 197 83
31 -39 1 178 197 83
32 -39 1 178 197 83
33 -39 1 178 197 83
34 -39 1 178 197 83
35 -39 1 178 197 83
36 -39 1 178 197 83
37 -39 1 178 197 83
38 -39 1 178 197 83
39 -39 1 178 197 83
40 -39 1 178 197 83
41 -39 1 178 197 83
42 -39 1 178 197 83
43 -39 1 178 197 83
44 -39 1 178 197 83
45 -39 1 178 197 83
46 -39 1 178 197 83
47 -39 1 178 197 83
48 -39 1 178 197 83
31 -38 1 103 113 88
32 -38 1 103 113 88
33 -38 1 103 113 88
31 -37 1 103 113 88
32 -37 1 103 113 88
33 -37 1 103 113 88
31 -36 1 103 113 88
32 -36 1 103 113 88
33 -36 1 103 113 88
-48 -39 2 178 197 83
-47 -39 2 178 197 83
-46 -39 2 178 197 83
-45 -39 2 178 197 83
-44 -39 2 178 197 83
-43 -39 2 178 197 83
-42 -39 2 178 197 83
-41 -39 2 178 197 83
-40 -39 2 178 197 83
-39 -39 2 178 197 83
-38 -39 2 178 197 83
-37 -39 2 178 197 83
-36 -39 2 178 197 83
-35 -39 2 178 197 83
-34 -39 2 178 197 83
-33 -39 2 178 197 83
-32 -39 2 178 197 83
-31 -39 2 178 197 83
-30 -39 2 178 197 83
-29 -39 2 178 197 83
-28 -39 2 178 197 83
-27 -39 2 178 197 83
-26 -39 2 178 197 83
-25 -39 2 178 197 83
-24 -39 2 178 197 83
-23 -39 2 178 197 83
-22 -39 2 178 197 83
-21 -39 2 178 197 83
-20 -39 2 178 197 83
-19 -39 2 178 197 83
-18 -39 2 178 197 83
-17 -39 2 178 197 83
-16 -39 2 178 197 83
-15 -39 2 178 197 83
-14 -39 2 178 197 83
-13 -39 2 178 197 83
-12 -39 2 178 197 83
-11 -39 2 178 197 83
-10 -39 2 178 197 83
-9 -39 2 178 197 83
-8 -39 2 178 197 83
-7 -39 2 178 197 83
-6 -39 2 178 197 83
-5 -39 2 178 197 83
-4 -39 2 178 197 83
-3 -39 2 178 197 83
-2 -39 2 178 197 83
-1 -39 2 178 197 83
0 -39 2 178 197 83
1 -39 2 178 197 83
2 -39 2 178 197 83
3 -39 2 178 197 83
4 -39 2 178 197 83
5 -39 2 178 197 83
6 -39 2 178 197 83
7 -39 2 178 197 83
8 -39 2 178 197 83
9 -39 2 178 197 83
10 -39 2 178 197 83
11 -39 2 178 197 83
12 -39 2 178 197 83
13 -39 2 178 197 83
14 -39 2 178 197 83
15 -39 2 178 197 83
16 -39 2 178 197 83
17 -39 2 178 197 83
18 -39 2 178 197 83
19 -39 2 178 197 83
20 -39 2 178 197 83
21 -39 2 178 197 83
22 -39 2 178 197 83
23 -39 2 178 197 83
24 -39 2 178 197 83
25 -39 2 178 197 83
26 -39 2 178 197 83
27 -39 2 178 197 83
28 -39 2 178 197 83
29 -39 2 178 197 83
30 -39 2 178 197 83
31 -39 2 178 197 83
32 -39 2 178 197 83
33 -39 2 178 197 83
34 -39 2 178 197 83
35 -39 2 178 197 83
36 -39 2 178 197 83
37 -39 2 178 197 83
38 -39 2 178 197 83
39 -39 2 178 197 83
40 -39 2 178 197 83
41 -39 2 178 197 83
42 -39 2 178 197 83
43 -39 2 178 197 83
44 -39 2 178 197 83
45 -39 2 178 197 83
46 -39 2 178 197 83
47 -39 2 178 197 83
48 -39 2 178 197 83
-39 -38 2 103 113 88
-38 -38 2 103 113 88
-37 -38 2 103 113 88
-25 -38 2 103 113 88
-24 -38 2 103 113 88
-23 -38 2 103 113 88
17 -38 2 103 113 88
18 -38 2 103 113 88
19 -38 2 103 113 88
31 -38 2 103 113 88
32 -38 2 103 113 88
33 -38 2 103 113 88
-39 -37 2 103 113 88
-38 -37 2 103 113 88
-37 -37 2 103 113 88
-25 -37 2 103 113 88
-24 -37 2 103 113 88
-23 -37 2 103 113 88
17 -37 2 103 113 88
18 -37 2 103 113 88
19 -37 2 103 113 88
31 -37 2 103 113 88
32 -37 2 103 113 88
33 -37 2 103 113 88
-39 -36 2 103 113 88
-38 -36 2 103 113 88
-37 -36 2 103 113 88
-25 -36 2 103 113 88
-24 -36 2 103 113 88
-23 -36 2 103 113 88
17 -36 2 103 113 88
18 -36 2 103 113 88
19 -36 2 103 113 88
31 -36 2 103 113 88
32 -36 2 103 113 88
33 -36 2 103 113 88
-39 -35 2 103 113 88
-38 -35 2 103 113 88
-37 -35 2 103 113 88
-25 -35 2 103 113 88
-24 -35 2 103 113 88
-23 -35 2 103 113 88
17 -35 2 103 113 88
18 -35 2 103 113 88
19 -35 2 103 113 88
-39 -34 2 103 113 88
-38 -34 2 103 113 88
-37 -34 2 103 113 88
-25 -34 2 103 113 88
-24 -34 2 103 113 88
-23 -34 2 103 113 88
-39 -33 2 103 113 88
-38 -33 2 103 113 88
-37 -33 2 103 113 88
-48 -39 3 178 197 83
-47 -39 3 178 197 83
-46 -39 3 178 197 83
-45 -39 3 178 197 83
-44 -39 3 178 197 83
-43 -39 3 178 197 83
-42 -39 3 178 197 83
-41 -39 3 178 197 83
-40 -39 3 178 197 83
-39 -39 3 178 197 83
-38 -39 3 178 197 83
-37 -39 3 178 197 83
-36 -39 3 178 197 83
-35 -39 3 178 197 83
-34 -39 3 178 197 83
-33 -39 3 178 197 83
-32 -39 3 178 197 83
-31 -39 3 178 197 83
-30 -39 3 178 197 83
-29 -39 3 178 197 83
-28 -39 3 178 197 83
-27 -39 3 178 197 83
-26 -39 3 178 197 83
-25 -39 3 178 197 83
-24 -39 3 178 197 83
-23 -39 3 178 197 83
-22 -39 3 178 197 83
-21 -39 3 178 197 83
-20 -39 3 178 197 83
-19 -39 3 178 197 83
-18 -39 3 178 197 83
-17 -39 3 178 197 83
-16 -39 3 178 197 83
-15 -39 3 178 197 83
-14 -39 3 178 197 83
-13 -39 3 178 197 83
-12 -39 3 178 197 83
-11 -39 3 178 197 83
-10 -39 3 178 197 83
-9 -39 3 178 197 83
-8 -39 3 178 197 83
-7 -39 3 178 197 83
-6 -39 3 178 197 83
-5 -39 3 178 197 83
-4 -39 3 178 197 83
-3 -39 3 178 197 83
-2 -39 3 178 197 83
-1 -39 3 178 197 83
0 -39 3 178 197 83
1 -39 3 178 197 83
2 -39 3 178 197 83
3 -39 3 178 197 83
4 -39 3 178 197 83
5 -39 3 178 197 83
6 -39 3 178 197 83
7 -39 3 178 197 83
8 -39 3 178 197 83
9 -39 3 178 197 83
10 -39 3 178 197 83
11 -39 3 178 197 83
12 -39 3 178 197 83
13 -39 3 178 197 83
14 -39 3 178 197 83
15 -39 3 178 197 83
16 -39 3 178 197 83
17 -39 3 178 197 83
18 -39 3 178 197 83
19 -39 3 178 197 83
20 -39 3 178 197 83
21 -39 3 178 197 83
22 -39 3 178 197 83
23 -39 3 178 197 83
24 -39 3 178 197 83
25 -39 3 178 197 83
26 -39 3 178 197 83
27 -39 3 178 197 83
28 -39 3 178 197 83
29 -39 3 178 197 83
30 -39 3 178 197 83
31 -39 3 178 197 83
32 -39 3 178 197 83
33 -39 3 178 197 83
34 -39 3 178 197 83
35 -39 3 178 197 83
36 -39 3 178 197 83
37 -39 3 178 197 83
38 -39 3 178 197 83
39 -39 3 178 197 83
40 -39 3 178 197 83
41 -39 3 178 197 83
42 -39 3 178 197 83
43 -39 3 178 197 83
44 -39 3 178 197 83
45 -39 3 178 197 83
46 -39 3 178 197 83
47 -39 3 178 197 83
48 -39 3 178 197 83
-39 -38 3 103 113 88
-38 -38 3 103 113 88
-37 -38 3 103 113 88
-25 -38 3 103 113 88
-24 -38 3 103 113 88
-23 -38 3 103 113 88
17 -38 3 103 113 88
18 -38 3 103 113 88
19 -38 3 103 113 88
-39 -37 3 103 113 88
-38 -37 3 103 113 88
-37 -37 3 103 113 88
-25 -37 3 103 113 88
-24 -37 3 103 113 88
-23 -37 3 103 113 88
17 -37 3 103 113 88
18 -37 3 103 113 88
19 -37 3 103 113 88
-39 -36 3 103 113 88
-38 -36 3 103 113 88
-37 -36 3 103 113 88
-25 -36 3 103 113 88
-24 -36 3 103 113 88
-23 -36 3 103 113 88
17 -36 3 103 113 88
18 -36 3 103 113 88
19 -36 3 103 113 88
-39 -35 3 103 113 88
-38 -35 3 103 113 88
-37 -35 3 103 113 88
-25 -35 3 103 113 88
-24 -35 3 103 113 88
-23 -35 3 103 113 88
17 -35 3 103 113 88
18 -35 3 103 113 88
19 -35 3 103 113 88
-39 -34 3 103 113 88
-38 -34 3 103 113 88
-37 -34 3 103 113 88
-25 -34 3 103 113 88
-24 -34 3 103 113 88
-23 -34 3 103 113 88
-39 -33 3 103 113 88
-38 -33 3 103 113 88
-37 -33 3 103 113 88
-48 -39 4 178 197 83
-47 -39 4 178 197 83
-46 -39 4 178 197 83
-45 -39 4 178 197 83
-44 -39 4 178 197 83
-43 -39 4 178 197 83
-42 -39 4 178 197 83
-41 -39 4 178 197 83
-40 -39 4 178 197 83
-39 -39 4 178 197 83
-38 -39 4 178 197 83
-37 -39 4 178 197 83
-36 -39 4 178 197 83
-35 -39 4 178 197 83
-34 -39 4 178 197 83
-33 -39 4 178 197 83
-32 -39 4 178 197 83
-31 -39 4 178 197 83
-30 -39 4 178 197 83
-29 -39 4 178 197 83
-28 -39 4 178 197 83
-27 -39 4 178 197 83
-26 -39 4 178 197 83
-25 -39 4 178 197 83
-24 -39 4 178 197 83
-23 -39 4 178 197 83
-22 -39 4 178 197 83
-21 -39 4 178 197 83
-20 -39 4 178 197 83
-19 -39 4 178 197 83
-18 -39 4 178 197 83
-17 -39 4 178 197 83
-16 -39 4 178 197 83
-15 -39 4 178 197 83
-14 -39 4 178 197 83
-13 -39 4 178 197 83
-12 -39 4 178 197 83
-11 -39 4 178 197 83
-10 -39 4 178 197 83
-9 -39 4 178 197 83
-8 -39 4 178 197 83
-7 -39 4 178 197 83
-6 -39 4 178 197 83
-5 -39 4 178 197 83
-4 -39 4 178 197 83
-3 -39 4 178 197 83
-2 -39 4 178 197 83
-1 -39 4 178 197 83
0 -39 4 178 197 83
1 -39 4 178 197 83
2 -39 4 178 197 83
3 -39 4 178 197 83
4 -39 4 178 197 83
5 -39 4 178 197 83
6 -39 4 178 197 83
7 -39 4 178 197 83
8 -39 4 178 197 83
9 -39 4 178 197 83
10 -39 4 178 197 83
11 -39 4 178 197 83
12 -39 4 178 197 83
13 -39 4 178 197 83
14 -39 4 178 197 83
15 -39 4 178 197 83
16 -39 4 178 197 83
17 -39 4 178 197 83
18 -39 4 178 197 83
19 -39 4 178 197 83
20 -39 4 178 197 83
21 -39 4 178 197 83
22 -39 4 178 197 83
23 -39 4 178 197 83
24 -39 4 178 197 83
25 -39 4 178 197 83
26 -39 4 178 197 83
27 -39 4 178 197 83
28 -39 4 178 197 83
29 -39 4 178 197 83
30 -39 4 178 197 83
31 -39 4 178 197 83
32 -39 4 178 197 83
33 -39 4 178 197 83
34 -39 4 178 197 83
35 -39 4 178 197 83
36 -39 4 178 197 83
37 -39 4 178 197 83
38 -39 4 178 197 83
39 -39 4 178 197 83
40 -39 4 178 197 83
41 -39 4 178 197 83
42 -39 4 178 197 83
43 -39 4 178 197 83
44 -39 4 178 197 83
45 -39 4 178 197 83
46 -39 4 178 197 83
47 -39 4 178 197 83
48 -39 4 178 197 83
-39 -38 4 103 113 88
-38 -38 4 103 113 88
-37 -38 4 103 113 88
-25 -38 4 103 113 88
-24 -38 4 103 113 88
-23 -38 4 103 113 88
17 -38 4 103 113 88
18 -38 4 103 113 88
19 -38 4 103 113 88
-39 -37 4 103 113 88
-38 -37 4 103 113 88
-37 -37 4 103 113 88
-25 -37 4 103 113 88
-24 -37 4 103 113 88
-23 -37 4 103 113 88
-10 -37 4 255 255 255
17 -37 4 103 113 88
18 -37 4 103 113 88
19 -37 4 103 113 88
-39 -36 4 103 113 88
-38 -36 4 103 113 88
-37 -36 4 103 113 88
-25 -36 4 103 113 88
-24 -36 4 103 113 88
-23 -36 4 103 113 88
17 -36 4 103 113 88
18 -36 4 103 113 88
19 -36 4 103 113 88
-39 -35 4 103 113 88
-38 -35 4 103 113 88
-37 -35 4 103 113 88
-25 -35 4 103 113 88
-24 -35 4 103 113 88
-23 -35 4 103 113 88
17 -35 4 103 113 88
18 -35 4 103 113 88
19 -35 4 103 113 88
-39 -34 4 103 113 88
-38 -34 4 103 113 88
-37 -34 4 103 113 88
-25 -34 4 103 113 88
-24 -34 4 103 113 88
-23 -34 4 103 113 88
-39 -33 4 103 113 88
-38 -33 4 103 113 88
-37 -33 4 103 113 88
-48 -39 5 178 197 83
-47 -39 5 178 197 83
-46 -39 5 178 197 83
-45 -39 5 178 197 83
-44 -39 5 178 197 83
-43 -39 5 178 197 83
-42 -39 5 178 197 83
-41 -39 5 178 197 83
-40 -39 5 178 197 83
-39 -39 5 178 197 83
-38 -39 5 178 197 83
-37 -39 5 178 197 83
-36 -39 5 178 197 83
-35 -39 5 178 197 83
-34 -39 5 178 197 83
-33 -39 5 178 197 83
-32 -39 5 178 197 83
-31 -39 5 178 197 83
-30 -39 5 178 197 83
-29 -39 5 178 197 83
-28 -39 5 178 197 83
-27 -39 5 178 197 83
-26 -39 5 178 197 83
-25 -39 5 178 197 83
-24 -39 5 178 197 83
-23 -39 5 178 197 83
-22 -39 5 178 197 83
-21 -39 5 178 197 83
-20 -39 5 178 197 83
-19 -39 5 178 197 83
-18 -39 5 178 197 83
-17 -39 5 178 197 83
-16 -39 5 178 197 83
-15 -39 5 178 197 83
-14 -39 5 178 197 83
-13 -39 5 178 197 83
-12 -39 5 178 197 83
-11 -39 5 178 197 83
-10 -39 5 178 197 83
-9 -39 5 178 197 83
-8 -39 5 178 197 83
-7 -39 5 178 197 83
-6 -39 5 178 197 83
-5 -39 5 178 197 83
-4 -39 5 178 197 83
-3 -39 5 178 197 83
-2 -39 5 178 197 83
-1 -39 5 178 197 83
0 -39 5 178 197 83
1 -39 5 178 197 83
2 -39 5 178 197 83
3 -39 5 178 197 83
4 -39 5 178 197 83
5 -39 5 178 197 83
6 -39 5 178 197 83
7 -39 5 178 197 83
8 -39 5 178 197 83
9 -39 5 178 197 83
10 -39 5 178 197 83
11 -39 5 178 197 83
12 -39 5 178 197 83
13 -39 5 178 197 83
14 -39 5 178 197 83
15 -39 5 178 197 83
16 -39 5 178 197 83
17 -39 5 178 197 83
18 -39 5 178 197 83
19 -39 5 178 197 83
20 -39 5 178 197 83
21 -39 5 178 197 83
22 -39 5 178 197 83
23 -39 5 178 197 83
24 -39 5 178 197 83
25 -39 5 178 197 83
26 -39 5 178 197 83
27 -39 5 178 197 83
28 -39 5 178 197 83
29 -39 5 178 197 83
30 -39 5 178 197 83
31 -39 5 178 197 83
32 -39 5 178 197 83
33 -39 5 178 197 83
34 -39 5 178 197 83
35 -39 5 178 197 83
36 -39 5 178 197 83
37 -39 5 178 197 83
38 -39 5 178 197 83
39 -39 5 178 197 83
40 -39 5 178 197 83
41 -39 5 178 197 83
42 -39 5 178 197 83
43 -39 5 178 197 83
44 -39 5 178 197 83
45 -39 5 178 197 83
46 -39 5 178 197 83
47 -39 5 178 197 83
48 -39 5 178 197 83
-21 -38 5 103 113 88
-20 -38 5 103 113 88
-10 -38 5 255 255 255
-21 -37 5 103 113 88
-20 -37 5 103 113 88
-11 -37 5 255 255 255
-10 -37 5 255 255 255
-9 -37 5 255 255 255
2 -37 5 255 255 255
-48 -39 6 178 197 83
-47 -39 6 178 197 83
-46 -39 6 178 197 83
-45 -39 6 178 197 83
-44 -39 6 178 197 83
-43 -39 6 178 197 83
-42 -39 6 178 197 83
-41 -39 6 178 197 83
-40 -39 6 178 197 83
-39 -39 6 178 197 83
-38 -39 6 178 197 83
-37 -39 6 178 197 83
-36 -39 6 178 197 83
-35 -39 6 178 197 83
-34 -39 6 178 197 83
-33 -39 6 178 197 83
-32 -39 6 178 197 83
-31 -39 6 178 197 83
-30 -39 6 178 197 83
-29 -39 6 178 197 83
-28 -39 6 178 197 83
-27 -39 6 178 197 83
-26 -39 6 178 197 83
-25 -39 6 178 197 83
-24 -39 6 178 197 83
-23 -39 6 178 197 83
-22 -39 6 178 197 83
-21 -39 6 178 197 83
-20 -39 6 178 197 83
-19 -39 6 178 197 83
-18 -39 6 178 197 83
-17 -39 6 178 197 83
-16 -39 6 178 197 83
-15 -39 6 178 197 83
-14 -39 6 178 197 83
-13 -39 6 178 197 83
-12 -39 6 178 197 83
-11 -39 6 178 197 83
-10 -39 6 178 197 83
-9 -39 6 178 197 83
-8 -39 6 178 197 83
-7 -39 6 178 197 83
-6 -39 6 178 197 83
-5 -39 6 178 197 83
-4 -39 6 178 197 83
-3 -39 6 178 197 83
-2 -39 6 178 197 83
-1 -39 6 178 197 83
0 -39 6 178 197 83
1 -39 6 178 197 83
2 -39 6 178 197 83
3 -39 6 178 197 83
4 -39 6 178 197 83
5 -39 6 178 197 83
6 -39 6 178 197 83
7 -39 6 178 197 83
8 -39 6 178 197 83
9 -39 6 178 197 83
10 -39 6 178 197 83
11 -39 6 178 197 83
12 -39 6 178 197 83
13 -39 6 178 197 83
14 -39 6 178 197 83
15 -39 6 178 197 83
16 -39 6 178 197 83
17 -39 6 178 197 83
18 -39 6 178 197 83
19 -39 6 178 197 83
20 -39 6 178 197 83
21 -39 6 178 197 83
22 -39 6 178 197 83
23 -39 6 178 197 83
24 -39 6 178 197 83
25 -39 6 178 197 83
26 -39 6 178 197 83
27 -39 6 178 197 83
28 -39 6 178 197 83
29 -39 6 178 197 83
30 -39 6 178 197 83
31 -39 6 178 197 83
32 -39 6 178 197 83
33 -39 6 178 197 83
34 -39 6 178 197 83
35 -39 6 178 197 83
36 -39 6 178 197 83
37 -39 6 178 197 83
38 -39 6 178 197 83
39 -39 6 178 197 83
40 -39 6 178 197 83
41 -39 6 178 197 83
42 -39 6 178 197 83
43 -39 6 178 197 83
44 -39 6 178 197 83
45 -39 6 178 197 83
46 -39 6 178 197 83
47 -39 6 178 197 83
48 -39 6 178 197 83
-21 -38 6 103 113 88
-20 -38 6 103 113 88
2 -38 6 255 255 255
-21 -37 6 103 113 88
-20 -37 6 103 113 88
-10 -37 6 255 255 255
1 -37 6 255 255 255
2 -37 6 255 255 255
3 -37 6 255 255 255
-48 -39 7 178 197 83
-47 -39 7 178 197 83
-46 -39 7 178 197 83
-45 -39 7 178 197 83
-44 -39 7 178 197 83
-43 -39 7 178 197 83
-42 -39 7 178 197 83
-41 -39 7 178 197 83
-40 -39 7 178 197 83
-39 -39 7 178 197 83
-38 -39 7 178 197 83
-37 -39 7 178 197 83
-36 -39 7 178 197 83
-35 -39 7 178 197 83
-34 -39 7 178 197 83
-33 -39 7 178 197 83
-32 -39 7 178 197 83
-31 -39 7 178 197 83
-30 -39 7 178 197 83
-29 -39 7 178 197 83
-28 -39 7 178 197 83
-27 -39 7 178 197 83
-26 -39 7 178 197 83
-25 -39 7 178 197 83
-24 -39 7 178 197 83
-23 -39 7 178 197 83
-22 -39 7 178 197 83
-21 -39 7 178 197 83
-20 -39 7 178 197 83
-19 -39 7 178 197 83
-18 -39 7 178 197 83
-17 -39 7 178 197 83
-16 -39 7 178 197 83
-15 -39 7 178 197 83
-14 -39 7 178 197 83
-13 -39 7 178 197 83
-12 -39 7 178 197 83
-11 -39 7 178 197 83
-10 -39 7 178 197 83
-9 -39 7 178 197 83
-8 -39 7 178 197 83
-7 -39 7 178 197 83
-6 -39 7 178 197 83
-5 -39 7 178 197 83
-4 -39 7 178 197 83
-3 -39 7 178 197 83
-2 -39 7 178 197 83
-1 -39 7 178 197 83
0 -39 7 178 197 83
1 -39 7 178 197 83
2 -39 7 178 197 83
3 -39 7 178 197 83
4 -39 7 178 197 83
5 -39 7 178 197 83
6 -39 7 178 197 83
7 -39 7 178 197 83
8 -39 7 178 197 83
9 -39 7 178 197 83
10 -39 7 178 197 83
11 -39 7 178 197 83
12 -39 7 178 197 83
13 -39 7 178 197 83
14 -39 7 178 197 83
15 -39 7 178 197 83
16 -39 7 178 197 83
17 -39 7 178 197 83
18 -39 7 178 197 83
19 -39 7 178 197 83
20 -39 7 178 197 83
21 -39 7 178 197 83
22 -39 7 178 197 83
23 -39 7 178 197 83
24 -39 7 178 197 83
25 -39 7 178 197 83
26 -39 7 178 197 83
27 -39 7 178 197 83
28 -39 7 178 197 83
29 -39 7 178 197 83
30 -39 7 178 197 83
31 -39 7 178 197 83
32 -39 7 178 197 83
33 -39 7 178 197 83
34 -39 7 178 197 83
35 -39 7 178 197 83
36 -39 7 178 197 83
37 -39 7 178 197 83
38 -39 7 178 197 83
39 -39 7 178 197 83
40 -39 7 178 197 83
41 -39 7 178 197 83
42 -39 7 178 197 83
43 -39 7 178 197 83
44 -39 7 178 197 83
45 -39 7 178 197 83
46 -39 7 178 197 83
47 -39 7 178 197 83
48 -39 7 178 197 83
2 -37 7 255 255 255
33 -37 7 255 255 255
-48 -39 8 178 197 83
-47 -39 8 178 197 83
-46 -39 8 178 197 83
-45 -39 8 178 197 83
-44 -39 8 178 197 83
-43 -39 8 178 197 83
-42 -39 8 178 197 83
-41 -39 8 178 197 83
-40 -39 8 178 197 83
-39 -39 8 178 197 83
-38 -39 8 178 197 83
-37 -39 8 178 197 83
-36 -39 8 178 197 83
-35 -39 8 178 197 83
-34 -39 8 178 197 83
-33 -39 8 178 197 83
-32 -39 8 178 197 83
-31 -39 8 178 197 83
-30 -39 8 178 197 83
-29 -39 8 178 197 83
-28 -39 8 178 197 83
-27 -39 8 178 197 83
-26 -39 8 178 197 83
-25 -39 8 178 197 83
-24 -39 8 178 197 83
-23 -39 8 178 197 83
-22 -39 8 178 197 83
-21 -39 8 178 197 83
-20 -39 8 178 197 83
-19 -39 8 178 197 83
-18 -39 8 178 197 83
-17 -39 8 178 197 83
-16 -39 8 178 197 83
-15 -39 8 178 197 83
-14 -39 8 178 197 83
-13 -39 8 178 197 83
-12 -39 8 178 197 83
-11 -39 8 178 197 83
-10 -39 8 178 197 83
-9 -39 8 178 197 83
-8 -39 8 178 197 83
-7 -39 8 178 197 83
-6 -39 8 178 197 83
-5 -39 8 178 197 83
-4 -39 8 178 197 83
-3 -39 8 178 197 83
-2 -39 8 178 197 83
-1 -39 8 178 197 83
0 -39 8 178 197 83
1 -39 8 178 197 83
2 -39 8 178 197 83
3 -39 8 178 197 83
4 -39 8 178 197 83
5 -39 8 178 197 83
6 -39 8 178 197 83
7 -39 8 178 197 83
8 -39 8 178 197 83
9 -39 8 178 197 83
10 -39 8 178 197 83
11 -39 8 178 197 83
12 -39 8 178 197 83
13 -39 8 178 197 83
14 -39 8 178 197 83
15 -39 8 178 197 83
16 -39 8 178 197 83
17 -39 8 178 197 83
18 -39 8 178 197 83
19 -39 8 178 197 83
20 -39 8 178 197 83
21 -39 8 178 197 83
22 -39 8 178 197 83
23 -39 8 178 197 83
24 -39 8 178 197 83
25 -39 8 178 197 83
26 -39 8 178 197 83
27 -39 8 178 197 83
28 -39 8 178 197 83
29 -39 8 178 197 83
30 -39 8 178 197 83
31 -39 8 178 197 83
32 -39 8 178 197 83
33 -39 8 178 197 83
34 -39 8 178 197 83
35 -39 8 178 197 83
36 -39 8 178 197 83
37 -39 8 178 197 83
38 -39 8 178 197 83
39 -39 8 178 197 83
40 -39 8 178 197 83
41 -39 8 178 197 83
42 -39 8 178 197 83
43 -39 8 178 197 83
44 -39 8 178 197 83
45 -39 8 178 197 83
46 -39 8 178 197 83
47 -39 8 178 197 83
48 -39 8 178 197 83
-24 -38 8 103 113 88
-23 -38 8 103 113 88
-22 -38 8 103 113 88
33 -38 8 255 255 255
-24 -37 8 103 113 88
-23 -37 8 103 113 88
-22 -37 8 103 113 88
32 -37 8 255 255 255
33 -37 8 255 255 255
34 -37 8 255 255 255
-24 -36 8 103 113 88
-23 -36 8 103 113 88
-22 -36 8 103 113 88
-24 -35 8 103 113 88
-23 -35 8 103 113 88
-22 -35 8 103 113 88
-24 -34 8 103 113 88
-23 -34 8 103 113 88
-22 -34 8 103 113 88
-24 -33 8 103 113 88
-23 -33 8 103 113 88
-22 -33 8 103 113 88
-24 -32 8 103 113 88
-23 -32 8 103 113 88
-22 -32 8 103 113 88
-48 -39 9 178 197 83
-47 -39 9 178 197 83
-46 -39 9 178 197 83
-45 -39 9 178 197 83
-44 -39 9 178 197 83
-43 -39 9 178 197 83
-42 -39 9 178 197 83
-41 -39 9 178 197 83
-40 -39 9 178 197 83
-39 -39 9 178 197 83
-38 -39 9 178 197 83
-37 -39 9 178 197 83
-36 -39 9 178 197 83
-35 -39 9 178 197 83
-34 -39 9 178 197 83
-33 -39 9 178 197 83
-32 -39 9 178 197 83
-31 -39 9 178 197 83
-30 -39 9 178 197 83
-29 -39 9 178 197 83
-28 -39 9 178 197 83
-27 -39 9 178 197 83
-26 -39 9 178 197 83
-25 -39 9 178 197 83
-24 -39 9 178 197 83
-23 -39 9 178 197 83
-22 -39 9 178 197 83
-21 -39 9 178 197 83
-20 -39 9 178 197 83
-19 -39 9 178 197 83
-18 -39 9 178 197 83
-17 -39 9 178 197 83
-16 -39 9 178 197 83
-15 -39 9 178 197 83
-14 -39 9 178 197 83
-13 -39 9 178 197 83
-12 -39 9 178 197 83
-11 -39 9 178 197 83
-10 -39 9 178 197 83
-9 -39 9 178 197 83
-8 -39 9 178 197 83
-7 -39 9 178 197 83
-6 -39 9 178 197 83
-5 -39 9 178 197 83
-4 -39 9 178 197 83
-3 -39 9 178 197 83
-2 -39 9 178 197 83
-1 -39 9 178 197 83
0 -39 9 178 197 83
1 -39 9 178 197 83
2 -39 9 178 197 83
3 -39 9 178 197 83
4 -39 9 178 197 83
5 -39 9 178 197 83
6 -39 9 178 197 83
7 -39 9 178 197 83
8 -39 9 178 197 83
9 -39 9 178 197 83
10 -39 9 178 197 83
11 -39 9 178 197 83
12 -39 9 178 197 83
13 -39 9 178 197 83
14 -39 9 178 197 83
15 -39 9 178 197 83
16 -39 9 178 197 83
17 -39 9 178 197 83
18 -39 9 178 197 83
19 -39 9 178 197 83
20 -39 9 178 197 83
21 -39 9 178 197 83
22 -39 9 178 197 83
23 -39 9 178 197 83
24 -39 9 178 197 83
25 -39 9 178 197 83
26 -39 9 178 197 83
27 -39 9 178 197 83
28 -39 9 178 197 83
29 -39 9 178 197 83
30 -39 9 178 197 83
31 -39 9 178 197 83
32 -39 9 178 197 83
33 -39 9 178 197 83
34 -39 9 178 197 83
35 -39 9 178 197 83
36 -39 9 178 197 83
37 -39 9 178 197 83
38 -39 9 178 197 83
39 -39 9 178 197 83
40 -39 9 178 197 83
41 -39 9 178 197 83
42 -39 9 178 197 83
43 -39 9 178 197 83
44 -39 9 178 197 83
45 -39 9 178 197 83
46 -39 9 178 197 83
47 -39 9 178 197 83
48 -39 9 178 197 83
-24 -38 9 103 113 88
-23 -38 9 103 113 88
-22 -38 9 103 113 88
-24 -37 9 103 113 88
-23 -37 9 103 113 88
-22 -37 9 103 113 88
33 -37 9 255 255 255
-24 -36 9 103 113 88
-23 -36 9 103 113 88
-22 -36 9 103 113 88
-24 -35 9 103 113 88
-23 -35 9 103 113 88
-22 -35 9 103 113 88
-24 -34 9 103 113 88
-23 -34 9 103 113 88
-22 -34 9 103 113 88
-24 -33 9 103 113 88
-23 -33 9 103 113 88
-22 -33 9 103 113 88
-24 -32 9 103 113 88
-23 -32 9 103 113 88
-22 -32 9 103 113 88
-48 -39 10 178 197 83
-47 -39 10 178 197 83
-46 -39 10 178 197 83
-45 -39 10 178 197 83
-44 -39 10 178 197 83
-43 -39 10 178 197 83
-42 -39 10 178 197 83
-41 -39 10 178 197 83
-40 -39 10 178 197 83
-39 -39 10 178 197 83
-38 -39 10 178 197 83
-37 -39 10 178 197 83
-36 -39 10 178 197 83
-35 -39 10 178 197 83
-34 -39 10 178 197 83
-33 -39 10 178 197 83
-32 -39 10 178 197 83
-31 -39 10 178 197 83
-30 -39 10 178 197 83
-29 -39 10 178 197 83
-28 -39 10 178 197 83
-27 -39 10 178 197 83
-26 -39 10 178 197 83
-25 -39 10 178 197 83
-24 -39 10 178 197 83
-23 -39 10 178 197 83
-22 -39 10 178 197 83
-21 -39 10 178 197 83
-20 -39 10 178 197 83
-19 -39 10 178 197 83
-18 -39 10 178 197 83
-17 -39 10 178 197 83
-16 -39 10 178 197 83
-15 -39 10 178 197 83
-14 -39 10 178 197 83
-13 -39 10 178 197 83
-12 -39 10 178 197 83
-11 -39 10 178 197 83
-10 -39 10 178 197 83
-9 -39 10 178 197 83
-8 -39 10 178 197 83
-7 -39 10 178 197 83
-6 -39 10 178 197 83
-5 -39 10 178 197 83
-4 -39 10 178 197 83
-3 -39 10 178 197 83
-2 -39 10 178 197 83
-1 -39 10 178 197 83
0 -39 10 178 197 83
1 -39 10 178 197 83
2 -39 10 178 197 83
3 -39 10 178 197 83
4 -39 10 178 197 83
5 -39 10 178 197 83
6 -39 10 178 197 83
7 -39 10 178 197 83
8 -39 10 178 197 83
9 -39 10 178 197 83
10 -39 10 178 197 83
11 -39 10 178 197 83
12 -39 10 178 197 83
13 -39 10 178 197 83
14 -39 10 178 197 83
15 -39 10 178 197 83
16 -39 10 178 197 83
17 -39 10 178 197 83
18 -39 10 178 197 83
19 -39 10 178 197 83
20 -39 10 178 197 83
21 -39 10 178 197 83
22 -39 10 178 197 83
23 -39 10 178 197 83
24 -39 10 178 197 83
25 -39 10 178 197 83
26 -39 10 178 197 83
27 -39 10 178 197 83
28 -39 10 178 197 83
29 -39 10 178 197 83
30 -39 10 178 197 83
31 -39 10 178 197 83
32 -39 10 178 197 83
33 -39 10 178 197 83
34 -39 10 178 197 83
35 -39 10 178 197 83
36 -39 10 178 197 83
37 -39 10 178 197 83
38 -39 10 178 197 83
39 -39 10 178 197 83
40 -39 10 178 197 83
41 -39 10 178 197 83
42 -39 10 178 197 83
43 -39 10 178 197 83
44 -39 10 178 197 83
45 -39 10 178 197 83
46 -39 10 178 197 83
47 -39 10 178 197 83
48 -39 10 178 197 83
-24 -38 10 103 113 88
-23 -38 10 103 113 88
-22 -38 10 103 113 88
-24 -37 10 103 113 88
-23 -37 10 103 113 88
-22 -37 10 103 113 88
-24 -36 10 103 113 88
-23 -36 10 103 113 88
-22 -36 10 103 113 88
-24 -35 10 103 113 88
-23 -35 10 103 113 88
-22 -35 10 103 113 88
-24 -34 10 103 113 88
-23 -34 10 103 113 88
-22 -34 10 103 113 88
-24 -33 10 103 113 88
-23 -33 10 103 113 88
-22 -33 10 103 113 88
-24 -32 10 103 113 88
-23 -32 10 103 113 88
-22 -32 10 103 113 88
-48 -39 11 178 197 83
-47 -39 11 178 197 83
-46 -39 11 178 197 83
-45 -39 11 178 197 83
-44 -39 11 178 197 83
-43 -39 11 178 197 83
-42 -39 11 178 197 83
-41 -39 11 178 197 83
-40 -39 11 178 197 83
-39 -39 11 178 197 83
-38 -39 11 178 197 83
-37 -39 11 178 197 83
-36 -39 11 178 197 83
-35 -39 11 178 197 83
-34 -39 11 178 197 83
-33 -39 11 178 197 83
-32 -39 11 178 197 83
-31 -39 11 178 197 83
-30 -39 11 178 197 83
-29 -39 11 178 197 83
-28 -39 11 178 197 83
-27 -39 11 178 197 83
-26 -39 11 178 197 83
-25 -39 11 178 197 83
-24 -39 11 178 197 83
-23 -39 11 178 197 83
-22 -39 11 178 197 83
-21 -39 11 178 197 83
-20 -39 11 178 197 83
-19 -39 11 178 197 83
-18 -39 11 178 197 83
-17 -39 11 178 197 83
-16 -39 11 178 197 83
-15 -39 11 178 197 83
-14 -39 11 178 197 83
-13 -39 11 178 197 83
-12 -39 11 178 197 83
-11 -39 11 178 197 83
-10 -39 11 178 197 83
-9 -39 11 178 197 83
-8 -39 11 178 197 83
-7 -39 11 178 197 83
-6 -39 11 178 197 83
-5 -39 11 178 197 83
-4 -39 11 178 197 83
-3 -39 11 178 197 83
-2 -39 11 178 197 83
-1 -39 11 178 197 83
0 -39 11 178 197 83
1 -39 11 178 197 83
2 -39 11 178 197 83
3 -39 11 178 197 83
4 -39 11 178 197 83
5 -39 11 178 197 83
6 -39 11 178 197 83
7 -39 11 178 197 83
8 -39 11 178 197 83
9 -39 11 178 197 83
10 -39 11 178 197 83
11 -39 11 178 197 83
12 -39 11 178 197 83
13 -39 11 178 197 83
14 -39 11 178 197 83
15 -39 11 178 197 83
16 -39 11 178 197 83
17 -39 11 178 197 83
18 -39 11 178 197 83
19 -39 11 178 197 83
20 -39 11 178 197 83
21 -39 11 178 197 83
22 -39 11 178 197 83
23 -39 11 178 197 83
24 -39 11 178 197 83
25 -39 11 178 197 83
26 -39 11 178 197 83
27 -39 11 178 197 83
28 -39 11 178 197 83
29 -39 11 178 197 83
30 -39 11 178 197 83
31 -39 11 178 197 83
32 -39 11 178 197 83
33 -39 11 178 197 83
34 -39 11 178 197 83
35 -39 11 178 197 83
36 -39 11 178 197 83
37 -39 11 178 197 83
38 -39 11 178 197 83
39 -39 11 178 197 83
40 -39 11 178 197 83
41 -39 11 178 197 83
42 -39 11 178 197 83
43 -39 11 178 197 83
44 -39 11 178 197 83
45 -39 11 178 197 83
46 -39 11 178 197 83
47 -39 11 178 197 83
48 -39 11 178 197 83
-24 -38 11 103 113 88
-23 -38 11 103 113 88
-22 -38 11 103 113 88
-16 -38 11 103 113 88
-15 -38 11 103 113 88
-14 -38 11 103 113 88
-24 -37 11 103 113 88
-23 -37 11 103 113 88
-22 -37 11 103 113 88
-16 -37 11 103 113 88
-15 -37 11 103 113 88
-14 -37 11 103 113 88
23 -37 11 255 255 255
-24 -36 11 103 113 88
-23 -36 11 103 113 88
-22 -36 11 103 113 88
-16 -36 11 103 113 88
-15 -36 11 103 113 88
-14 -36 11 103 113 88
-24 -35 11 103 113 88
-23 -35 11 103 113 88
-22 -35 11 103 113 88
-16 -35 11 103 113 88
-15 -35 11 103 113 88
-14 -35 11 103 113 88
-24 -34 11 103 113 88
-23 -34 11 103 113 88
-22 -34 11 103 113 88
-16 -34 11 103 113 88
-15 -34 11 103 113 88
-14 -34 11 103 113 88
-24 -33 11 103 113 88
-23 -33 11 103 113 88
-22 -33 11 103 113 88
-16 -33 11 103 113 88
-15 -33 11 103 113 88
-14 -33 11 103 113 88
-24 -32 11 103 113 88
-23 -32 11 103 113 88
-22 -32 11 103 113 88
-48 -39 12 178 197 83
-47 -39 12 178 197 83
-46 -39 12 178 197 83
-45 -39 12 178 197 83
-44 -39 12 178 197 83
-43 -39 12 178 197 83
-42 -39 12 178 197 83
-41 -39 12 178 197 83
-40 -39 12 178 197 83
-39 -39 12 178 197 83
-38 -39 12 178 197 83
-37 -39 12 178 197 83
-36 -39 12 178 197 83
-35 -39 12 178 197 83
-34 -39 12 178 197 83
-33 -39 12 178 197 83
-32 -39 12 178 197 83
-31 -39 12 178 197 83
-30 -39 12 178 197 83
-29 -39 12 178 197 83
-28 -39 12 178 197 83
-27 -39 12 178 197 83
-26 -39 12 178 197 83
-25 -39 12 178 197 83
-24 -39 12 178 197 83
-23 -39 12 178 197 83
-22 -39 12 178 197 83
-21 -39 12 178 197 83
-20 -39 12 178 197 83
-19 -39 12 178 197 83
-18 -39 12 178 197 83
-17 -39 12 178 197 83
-16 -39 12 178 197 83
-15 -39 12 178 197 83
-14 -39 12 178 197 83
-13 -39 12 178 197 83
-12 -39 12 178 197 83
-11 -39 12 178 197 83
-10 -39 12 178 197 83
-9 -39 12 178 197 83
-8 -39 12 178 197 83
-7 -39 12 178 197 83
-6 -39 12 178 197 83
-5 -39 12 178 197 83
-4 -39 12 178 197 83
-3 -39 12 178 197 83
-2 -39 12 178 197 83
-1 -39 12 178 197 83
0 -39 12 178 197 83
1 -39 12 178 197 83
2 -39 12 178 197 83
3 -39 12 178 197 83
4 -39 12 178 197 83
5 -39 12 178 197 83
6 -39 12 178 197 83
7 -39 12 178 197 83
8 -39 12 178 197 83
9 -39 12 178 197 83
10 -39 12 178 197 83
11 -39 12 178 197 83
12 -39 12 178 197 83
13 -39 12 178 197 83
14 -39 12 178 197 83
15 -39 12 178 197 83
16 -39 12 178 197 83
17 -39 12 178 197 83
18 -39 12 178 197 83
19 -39 12 178 197 83
20 -39 12 178 197 83
21 -39 12 178 197 83
22 -39 12 178 197 83
23 -39 12 178 197 83
24 -39 12 178 197 83
25 -39 12 178 197 83
26 -39 12 178 197 83
27 -39 12 178 197 83
28 -39 12 178 197 83
29 -39 12 178 197 83
30 -39 12 178 197 83
31 -39 12 178 197 83
32 -39 12 178 197 83
33 -39 12 178 197 83
34 -39 12 178 197 83
35 -39 12 178 197 83
36 -39 12 178 197 83
37 -39 12 178 197 83
38 -39 12 178 197 83
39 -39 12 178 197 83
40 -39 12 178 197 83
41 -39 12 178 197 83
42 -39 12 178 197 83
43 -39 12 178 197 83
44 -39 12 178 197 83
45 -39 12 178 197 83
46 -39 12 178 197 83
47 -39 12 178 197 83
48 -39 12 178 197 83
-16 -38 12 103 113 88
-15 -38 12 103 113 88
-14 -38 12 103 113 88
23 -38 12 255 255 255
-16 -37 12 103 113 88
-15 -37 12 103 113 88
-14 -37 12 103 113 88
22 -37 12 255 255 255
23 -37 12 255 255 255
24 -37 12 255 255 255
-16 -36 12 103 113 88
-15 -36 12 103 113 88
-14 -36 12 103 113 88
-16 -35 12 103 113 88
-15 -35 12 103 113 88
-14 -35 12 103 113 88
-16 -34 12 103 113 88
-15 -34 12 103 113 88
-14 -34 12 103 113 88
-16 -33 12 103 113 88
-15 -33 12 103 113 88
-14 -33 12 103 113 88
-48 -39 13 178 197 83
-47 -39 13 178 197 83
-46 -39 13 178 197 83
-45 -39 13 178 197 83
-44 -39 13 178 197 83
-43 -39 13 178 197 83
-42 -39 13 178 197 83
-41 -39 13 178 197 83
-40 -39 13 178 197 83
-39 -39 13 178 197 83
-38 -39 13 178 197 83
-37 -39 13 178 197 83
-36 -39 13 178 197 83
-35 -39 13 178 197 83
-34 -39 13 178 197 83
-33 -39 13 178 197 83
-32 -39 13 178 197 83
-31 -39 13 178 197 83
-30 -39 13 178 197 83
-29 -39 13 178 197 83
-28 -39 13 178 197 83
-27 -39 13 178 197 83
-26 -39 13 178 197 83
-25 -39 13 178 197 83
-24 -39 13 178 197 83
-23 -39 13 178 197 83
-22 -39 13 178 197 83
-21 -39 13 178 197 83
-20 -39 13 178 197 83
-19 -39 13 178 197 83
-18 -39 13 178 197 83
-17 -39 13 178 197 83
-16 -39 13 178 197 83
-15 -39 13 178 197 83
-14 -39 13 178 197 83
-13 -39 13 178 197 83
-12 -39 13 178 197 83
-11 -39 13 178 197 83
-10 -39 13 178 197 83
-9 -39 13 178 197 83
-8 -39 13 178 197 83
-7 -39 13 178 197 83
-6 -39 13 178 197 83
-5 -39 13 178 197 83
-4 -39 13 178 197 83
-3 -39 13 178 197 83
-2 -39 13 178 197 83
-1 -39 13 178 197 83
0 -39 13 178 197 83
1 -39 13 178 197 83
2 -39 13 178 197 83
3 -39 13 178 197 83
4 -39 13 178 197 83
5 -39 13 178 197 83
6 -39 13 178 197 83
7 -39 13 178 197 83
8 -39 13 178 197 83
9 -39 13 178 197 83
10 -39 13 178 197 83
11 -39 13 178 197 83
12 -39 13 178 197 83
13 -39 13 178 197 83
14 -39 13 178 197 83
15 -39 13 178 197 83
16 -39 13 178 197 83
17 -39 13 178 197 83
18 -39 13 178 197 83
19 -39 13 178 197 83
20 -39 13 178 197 83
21 -39 13 178 197 83
22 -39 13 178 197 83
23 -39 13 178 197 83
24 -39 13 178 197 83
25 -39 13 178 197 83
26 -39 13 178 197 83
27 -39 13 178 197 83
28 -39 13 178 197 83
29 -39 13 178 197 83
30 -39 13 178 197 83
31 -39 13 178 197 83
32 -39 13 178 197 83
33 -39 13 178 197 83
34 -39 13 178 197 83
35 -39 13 178 197 83
36 -39 13 178 197 83
37 -39 13 178 197 83
38 -39 13 178 197 83
39 -39 13 178 197 83
40 -39 13 178 197 83
41 -39 13 178 197 83
42 -39 13 178 197 83
43 -39 13 178 197 83
44 -39 13 178 197 83
45 -39 13 178 197 83
46 -39 13 178 197 83
47 -39 13 178 197 83
48 -39 13 178 197 83
-16 -38 13 103 113 88
-15 -38 13 103 113 88
-14 -38 13 103 113 88
-40 -37 13 255 255 255
-16 -37 13 103 113 88
-15 -37 13 103 113 88
-14 -37 13 103 113 88
23 -37 13 255 255 255
-16 -36 13 103 113 88
-15 -36 13 103 113 88
-14 -36 13 103 113 88
-16 -35 13 103 113 88
-15 -35 13 103 113 88
-14 -35 13 103 113 88
-16 -34 13 103 113 88
-15 -34 13 103 113 88
-14 -34 13 103 113 88
-16 -33 13 103 113 88
-15 -33 13 103 113 88
-14 -33 13 103 113 88
-48 -39 14 178 197 83
-47 -39 14 178 197 83
-46 -39 14 178 197 83
-45 -39 14 178 197 83
-44 -39 14 178 197 83
-43 -39 14 178 197 83
-42 -39 14 178 197 83
-41 -39 14 178 197 83
-40 -39 14 178 197 83
-39 -39 14 178 197 83
-38 -39 14 178 197 83
-37 -39 14 178 197 83
-36 -39 14 178 197 83
-35 -39 14 178 197 83
-34 -39 14 178 197 83
-33 -39 14 178 197 83
-32 -39 14 178 197 83
-31 -39 14 178 197 83
-30 -39 14 178 197 83
-29 -39 14 178 197 83
-28 -39 14 178 197 83
-27 -39 14 178 197 83
-26 -39 14 178 197 83
-25 -39 14 178 197 83
-24 -39 14 178 197 83
-23 -39 14 178 197 83
-22 -39 14 178 197 83
-21 -39 14 178 197 83
-20 -39 14 178 197 83
-19 -39 14 178 197 83
-18 -39 14 178 197 83
-17 -39 14 178 197 83
-16 -39 14 178 197 83
-15 -39 14 178 197 83
-14 -39 14 178 197 83
-13 -39 14 178 197 83
-12 -39 14 178 197 83
-11 -39 14 178 197 83
-10 -39 14 178 197 83
-9 -39 14 178 197 83
-8 -39 14 178 197 83
-7 -39 14 178 197 83
-6 -39 14 178 197 83
-5 -39 14 178 197 83
-4 -39 14 178 197 83
-3 -39 14 178 197 83
-2 -39 14 178 197 83
-1 -39 14 178 197 83
0 -39 14 178 197 83
1 -39 14 178 197 83
2 -39 14 178 197 83
3 -39 14 178 197 83
4 -39 14 178 197 83
5 -39 14 178 197 83
6 -39 14 178 197 83
7 -39 14 178 197 83
8 -39 14 178 197 83
9 -39 14 178 197 83
10 -39 14 178 197 83
11 -39 14 178 197 83
12 -39 14 178 197 83
13 -39 14 178 197 83
14 -39 14 178 197 83
15 -39 14 178 197 83
16 -39 14 178 197 83
17 -39 14 178 197 83
18 -39 14 178 197 83
19 -39 14 178 197 83
20 -39 14 178 197 83
21 -39 14 178 197 83
22 -39 14 178 197 83
23 -39 14 178 197 83
24 -39 14 178 197 83
25 -39 14 178 197 83
26 -39 14 178 197 83
27 -39 14 178 197 83
28 -39 14 178 197 83
29 -39 14 178 197 83
30 -39 14 178 197 83
31 -39 14 178 197 83
32 -39 14 178 197 83
33 -39 14 178 197 83
34 -39 14 178 197 83
35 -39 14 178 197 83
36 -39 14 178 197 83
37 -39 14 178 197 83
38 -39 14 178 197 83
39 -39 14 178 197 83
40 -39 14 178 197 83
41 -39 14 178 197 83
42 -39 14 178 197 83
43 -39 14 178 197 83
44 -39 14 178 197 83
45 -39 14 178 197 83
46 -39 14 178 197 83
47 -39 14 178 197 83
48 -39 14 178 197 83
-40 -38 14 255 255 255
-41 -37 14 255 255 255
-40 -37 14 255 255 255
-39 -37 14 255 255 255
-48 -39 15 178 197 83
-47 -39 15 178 197 83
-46 -39 15 178 197 83
-45 -39 15 178 197 83
-44 -39 15 178 197 83
-43 -39 15 178 197 83
-42 -39 15 178 197 83
-41 -39 15 178 197 83
-40 -39 15 178 197 83
-39 -39 15 178 197 83
-38 -39 15 178 197 83
-37 -39 15 178 197 83
-36 -39 15 178 197 83
-35 -39 15 178 197 83
-34 -39 15 178 197 83
-33 -39 15 178 197 83
-32 -39 15 178 197 83
-31 -39 15 178 197 83
-30 -39 15 178 197 83
-29 -39 15 178 197 83
-28 -39 15 178 197 83
-27 -39 15 178 197 83
-26 -39 15 178 197 83
-25 -39 15 178 197 83
-24 -39 15 178 197 83
-23 -39 15 178 197 83
-22 -39 15 178 197 83
-21 -39 15 178 197 83
-20 -39 15 178 197 83
-19 -39 15 178 197 83
-18 -39 15 178 197 83
-17 -39 15 178 197 83
-16 -39 15 178 197 83
-15 -39 15 178 197 83
-14 -39 15 178 197 83
-13 -39 15 178 197 83
-12 -39 15 178 197 83
-11 -39 15 178 197 83
-10 -39 15 178 197 83
-9 -39 15 178 197 83
-8 -39 15 178 197 83
-7 -39 15 178 197 83
-6 -39 15 178 197 83
-5 -39 15 178 197 83
-4 -39 15 178 197 83
-3 -39 15 178 197 83
-2 -39 15 178 197 83
-1 -39 15 178 197 83
0 -39 15 178 197 83
1 -39 15 178 197 83
2 -39 15 178 197 83
3 -39 15 178 197 83
4 -39 15 178 197 83
5 -39 15 178 197 83
6 -39 15 178 197 83
7 -39 15 178 197 83
8 -39 15 178 197 83
9 -39 15 178 197 83
10 -39 15 178 197 83
11 -39 15 178 197 83
12 -39 15 178 197 83
13 -39 15 178 197 83
14 -39 15 178 197 83
15 -39 15 178 197 83
16 -39 15 178 197 83
17 -39 15 178 197 83
18 -39 15 178 197 83
19 -39 15 178 197 83
20 -39 15 178 197 83
21 -39 15 178 197 83
22 -39 15 178 197 83
23 -39 15 178 197 83
24 -39 15 178 197 83
25 -39 15 178 197 83
26 -39 15 178 197 83
27 -39 15 178 197 83
28 -39 15 178 197 83
29 -39 15 178 197 83
30 -39 15 178 197 83
31 -39 15 178 197 83
32 -39 15 178 197 83
33 -39 15 178 197 83
34 -39 15 178 197 83
35 -39 15 178 197 83
36 -39 15 178 197 83
37 -39 15 178 197 83
38 -39 15 178 197 83
39 -39 15 178 197 83
40 -39 15 178 197 83
41 -39 15 178 197 83
42 -39 15 178 197 83
43 -39 15 178 197 83
44 -39 15 178 197 83
45 -39 15 178 197 83
46 -39 15 178 197 83
47 -39 15 178 197 83
48 -39 15 178 197 83
-40 -37 15 255 255 255
-48 -39 16 178 197 83
-47 -39 16 178 197 83
-46 -39 16 178 197 83
-45 -39 16 178 197 83
-44 -39 16 178 197 83
-43 -39 16 178 197 83
-42 -39 16 178 197 83
-41 -39 16 178 197 83
-40 -39 16 178 197 83
-39 -39 16 178 197 83
-38 -39 16 178 197 83
-37 -39 16 178 197 83
-36 -39 16 178 197 83
-35 -39 16 178 197 83
-34 -39 16 178 197 83
-33 -39 16 178 197 83
-32 -39 16 178 197 83
-31 -39 16 178 197 83
-30 -39 16 178 197 83
-29 -39 16 178 197 83
-28 -39 16 178 197 83
-27 -39 16 178 197 83
-26 -39 16 178 197 83
-25 -39 16 178 197 83
-24 -39 16 178 197 83
-23 -39 16 178 197 83
-22 -39 16 178 197 83
-21 -39 16 178 197 83
-20 -39 16 178 197 83
-19 -39 16 178 197 83
-18 -39 16 178 197 83
-17 -39 16 178 197 83
-16 -39 16 178 197 83
-15 -39 16 178 197 83
-14 -39 16 178 197 83
-13 -39 16 178 197 83
-12 -39 16 178 197 83
-11 -39 16 178 197 83
-10 -39 16 178 197 83
-9 -39 16 178 197 83
-8 -39 16 178 197 83
-7 -39 16 178 197 83
-6 -39 16 178 197 83
-5 -39 16 178 197 83
-4 -39 16 178 197 83
-3 -39 16 178 197 83
-2 -39 16 178 197 83
-1 -39 16 178 197 83
0 -39 16 178 197 83
1 -39 16 178 197 83
2 -39 16 178 197 83
3 -39 16 178 197 83
4 -39 16 178 197 83
5 -39 16 178 197 83
6 -39 16 178 197 83
7 -39 16 178 197 83
8 -39 16 178 197 83
9 -39 16 178 197 83
10 -39 16 178 197 83
11 -39 16 178 197 83
12 -39 16 178 197 83
13 -39 16 178 197 83
14 -39 16 178 197 83
15 -39 16 178 197 83
16 -39 16 178 197 83
17 -39 16 178 197 83
18 -39 16 178 197 83
19 -39 16 178 197 83
20 -39 16 178 197 83
21 -39 16 178 197 83
22 -39 16 178 197 83
23 -39 16 178 197 83
24 -39 16 178 197 83
25 -39 16 178 197 83
26 -39 16 178 197 83
27 -39 16 178 197 83
28 -39 16 178 197 83
29 -39 16 178 197 83
30 -39 16 178 197 83
31 -39 16 178 197 83
32 -39 16 178 197 83
33 -39 16 178 197 83
34 -39 16 178 197 83
35 -39 16 178 197 83
36 -39 16 178 197 83
37 -39 16 178 197 83
38 -39 16 178 197 83
39 -39 16 178 197 83
40 -39 16 178 197 83
41 -39 16 178 197 83
42 -39 16 178 197 83
43 -39 16 178 197 83
44 -39 16 178 197 83
45 -39 16 178 197 83
46 -39 16 178 197 83
47 -39 16 178 197 83
48 -39 16 178 197 83
-48 -39 17 178 197 83
-47 -39 17 178 197 83
-46 -39 17 178 197 83
-45 -39 17 178 197 83
-44 -39 17 178 197 83
-43 -39 17 178 197 83
-42 -39 17 178 197 83
-41 -39 17 178 197 83
-40 -39 17 178 197 83
-39 -39 17 178 197 83
-38 -39 17 178 197 83
-37 -39 17 178 197 83
-36 -39 17 178 197 83
-35 -39 17 178 197 83
-34 -39 17 178 197 83
-33 -39 17 178 197 83
-32 -39 17 178 197 83
-31 -39 17 178 197 83
-30 -39 17 178 197 83
-29 -39 17 178 197 83
-28 -39 17 178 197 83
-27 -39 17 178 197 83
-26 -39 17 178 197 83
-25 -39 17 178 197 83
-24 -39 17 178 197 83
-23 -39 17 178 197 83
-22 -39 17 178 197 83
-21 -39 17 178 197 83
-20 -39 17 178 197 83
-19 -39 17 178 197 83
-18 -39 17 178 197 83
-17 -39 17 178 197 83
-16 -39 17 178 197 83
-15 -39 17 178 197 83
-14 -39 17 178 197 83
-13 -39 17 178 197 83
-12 -39 17 178 197 83
-11 -39 17 178 197 83
-10 -39 17 178 197 83
-9 -39 17 178 197 83
-8 -39 17 178 197 83
-7 -39 17 178 197 83
-6 -39 17 178 197 83
-5 -39 17 178 197 83
-4 -39 17 178 197 83
-3 -39 17 178 197 83
-2 -39 17 178 197 83
-1 -39 17 178 197 83
0 -39 17 178 197 83
1 -39 17 178 197 83
2 -39 17 178 197 83
3 -39 17 178 197 83
4 -39 17 178 197 83
5 -39 17 178 197 83
6 -39 17 178 197 83
7 -39 17 178 197 83
8 -39 17 178 197 83
9 -39 17 178 197 83
10 -39 17 178 197 83
11 -39 17 178 197 83
12 -39 17 178 197 83
13 -39 17 178 197 83
14 -39 17 178 197 83
15 -39 17 178 197 83
16 -39 17 178 197 83
17 -39 17 178 197 83
18 -39 17 178 197 83
19 -39 17 178 197 83
20 -39 17 178 197 83
21 -39 17 178 197 83
22 -39 17 178 197 83
23 -39 17 178 197 83
24 -39 17 178 197 83
25 -39 17 178 197 83
26 -39 17 178 197 83
27 -39 17 178 197 83
28 -39 17 178 197 83
29 -39 17 178 197 83
30 -39 17 178 197 83
31 -39 17 178 197 83
32 -39 17 178 197 83
33 -39 17 178 197 83
34 -39 17 178 197 83
35 -39 17 178 197 83
36 -39 17 178 197 83
37 -39 17 178 197 83
38 -39 17 178 197 83
39 -39 17 178 197 83
40 -39 17 178 197 83
41 -39 17 178 197 83
42 -39 17 178 197 83
43 -39 17 178 197 83
44 -39 17 178 197 83
45 -39 17 178 197 83
46 -39 17 178 197 83
47 -39 17 178 197 83
48 -39 17 178 197 83
-48 -39 18 178 197 83
-47 -39 18 178 197 83
-46 -39 18 178 197 83
-45 -39 18 178 197 83
-44 -39 18 178 197 83
-43 -39 18 178 197 83
-42 -39 18 178 197 83
-41 -39 18 178 197 83
-40 -39 18 178 197 83
-39 -39 18 178 197 83
-38 -39 18 178 197 83
-37 -39 18 178 197 83
-36 -39 18 178 197 83
-35 -39 18 178 197 83
-34 -39 18 178 197 83
-33 -39 18 178 197 83
-32 -39 18 178 197 83
-31 -39 18 178 197 83
-30 -39 18 178 197 83
-29 -39 18 178 197 83
-28 -39 18 178 197 83
-27 -39 18 178 197 83
-26 -39 18 178 197 83
-25 -39 18 178 197 83
-24 -39 18 178 197 83
-23 -39 18 178 197 83
-22 -39 18 178 197 83
-21 -39 18 178 197 83
-20 -39 18 178 197 83
-19 -39 18 178 197 83
-18 -39 18 178 197 83
-17 -39 18 178 197 83
-16 -39 18 178 197 83
-15 -39 18 178 197 83
-14 -39 18 178 197 83
-13 -39 18 178 197 83
-12 -39 18 178 197 83
-11 -39 18 178 197 83
-10 -39 18 178 197 83
-9 -39 18 178 197 83
-8 -39 18 178 197 83
-7 -39 18 178 197 83
-6 -39 18 178 197 83
-5 -39 18 178 197 83
-4 -39 18 178 197 83
-3 -39 18 178 197 83
-2 -39 18 178 197 83
-1 -39 18 178 197 83
0 -39 18 178 197 83
1 -39 18 178 197 83
2 -39 18 178 197 83
3 -39 18 178 197 83
4 -39 18 178 197 83
5 -39 18 178 197 83
6 -39 18 178 197 83
7 -39 18 178 197 83
8 -39 18 178 197 83
9 -39 18 178 197 83
10 -39 18 178 197 83
11 -39 18 178 197 83
12 -39 18 178 197 83
13 -39 18 178 197 83
14 -39 18 178 197 83
15 -39 18 178 197 83
16 -39 18 178 197 83
17 -39 18 178 197 83
18 -39 18 178 197 83
19 -39 18 178 197 83
20 -39 18 178 197 83
21 -39 18 178 197 83
22 -39 18 178 197 83
23 -39 18 178 197 83
24 -39 18 178 197 83
25 -39 18 178 197 83
26 -39 18 178 197 83
27 -39 18 178 197 83
28 -39 18 178 197 83
29 -39 18 178 197 83
30 -39 18 178 197 83
31 -39 18 178 197 83
32 -39 18 178 197 83
33 -39 18 178 197 83
34 -39 18 178 197 83
35 -39 18 178 197 83
36 -39 18 178 197 83
37 -39 18 178 197 83
38 -39 18 178 197 83
39 -39 18 178 197 83
40 -39 18 178 197 83
41 -39 18 178 197 83
42 -39 18 178 197 83
43 -39 18 178 197 83
44 -39 18 178 197 83
45 -39 18 178 197 83
46 -39 18 178 197 83
47 -39 18 178 197 83
48 -39 18 178 197 83
-48 -39 19 178 197 83
-47 -39 19 178 197 83
-46 -39 19 178 197 83
-45 -39 19 178 197 83
-44 -39 19 178 197 83
-43 -39 19 178 197 83
-42 -39 19 178 197 83
-41 -39 19 178 197 83
-40 -39 19 178 197 83
-39 -39 19 178 197 83
-38 -39 19 178 197 83
-37 -39 19 178 197 83
-36 -39 19 178 197 83
-35 -39 19 178 197 83
-34 -39 19 178 197 83
-33 -39 19 178 197 83
-32 -39 19 178 197 83
-31 -39 19 178 197 83
-30 -39 19 178 197 83
-29 -39 19 178 197 83
-28 -39 19 178 197 83
-27 -39 19 178 197 83
-26 -39 19 178 197 83
-25 -39 19 178 197 83
-24 -39 19 178 197 83
-23 -39 19 178 197 83
-22 -39 19 178 197 83
-21 -39 19 178 197 83
-20 -39 19 178 197 83
-19 -39 19 178 197 83
-18 -39 19 178 197 83
-17 -39 19 178 197 83
-16 -39 19 178 197 83
-15 -39 19 178 197 83
-14 -39 19 178 197 83
-13 -39 19 178 197 83
-12 -39 19 178 197 83
-11 -39 19 178 197 83
-10 -39 19 178 197 83
-9 -39 19 178 197 83
-8 -39 19 178 197 83
-7 -39 19 178 197 83
-6 -39 19 178 197 83
-5 -39 19 178 197 83
-4 -39 19 178 197 83
-3 -39 19 178 197 83
-2 -39 19 178 197 83
-1 -39 19 178 197 83
0 -39 19 178 197 83
1 -39 19 178 197 83
2 -39 19 178 197 83
3 -39 19 178 197 83
4 -39 19 178 197 83
5 -39 19 178 197 83
6 -39 19 178 197 83
7 -39 19 178 197 83
8 -39 19 178 197 83
9 -39 19 178 197 83
10 -39 19 178 197 83
11 -39 19 178 197 83
12 -39 19 178 197 83
13 -39 19 178 197 83
14 -39 19 178 197 83
15 -39 19 178 197 83
16 -39 19 178 197 83
17 -39 19 178 197 83
18 -39 19 178 197 83
19 -39 19 178 197 83
20 -39 19 178 197 83
21 -39 19 178 197 83
22 -39 19 178 197 83
23 -39 19 178 197 83
24 -39 19 178 197 83
25 -39 19 178 197 83
26 -39 19 178 197 83
27 -39 19 178 197 83
28 -39 19 178 197 83
29 -39 19 178 197 83
30 -39 19 178 197 83
31 -39 19 178 197 83
32 -39 19 178 197 83
33 -39 19 178 197 83
34 -39 19 178 197 83
35 -39 19 178 197 83
36 -39 19 178 197 83
37 -39 19 178 197 83
38 -39 19 178 197 83
39 -39 19 178 197 83
40 -39 19 178 197 83
41 -39 19 178 197 83
42 -39 19 178 197 83
43 -39 19 178 197 83
44 -39 19 178 197 83
45 -39 19 178 197 83
46 -39 19 178 197 83
47 -39 19 178 197 83
48 -39 19 178 197 83
-48 -39 20 178 197 83
-47 -39 20 178 197 83
-46 -39 20 178 197 83
-45 -39 20 178 197 83
-44 -39 20 178 197 83
-43 -39 20 178 197 83
-42 -39 20 178 197 83
-41 -39 20 178 197 83
-40 -39 20 178 197 83
-39 -39 20 178 197 83
-38 -39 20 178 197 83
-37 -39 20 178 197 83
-36 -39 20 178 197 83
-35 -39 20 178 197 83
-34 -39 20 178 197 83
-33 -39 20 178 197 83
-32 -39 20 178 197 83
-31 -39 20 178 197 83
-30 -39 20 178 197 83
-29 -39 20 178 197 83
-28 -39 20 178 197 83
-27 -39 20 178 197 83
-26 -39 20 178 197 83
-25 -39 20 178 197 83
-24 -39 20 178 197 83
-23 -39 20 178 197 83
-22 -39 20 178 197 83
-21 -39 20 178 197 83
-20 -39 20 178 197 83
-19 -39 20 178 197 83
-18 -39 20 178 197 83
-17 -39 20 178 197 83
-16 -39 20 178 197 83
-15 -39 20 178 197 83
-14 -39 20 178 197 83
-13 -39 20 178 197 83
-12 -39 20 178 197 83
-11 -39 20 178 197 83
-10 -39 20 178 197 83
-9 -39 20 178 197 83
-8 -39 20 178 197 83
-7 -39 20 178 197 83
-6 -39 20 178 197 83
-5 -39 20 178 197 83
-4 -39 20 178 197 83
-3 -39 20 178 197 83
-2 -39 20 178 197 83
-1 -39 20 178 197 83
0 -39 20 178 197 83
1 -39 20 178 197 83
2 -39 20 178 197 83
3 -39 20 178 197 83
4 -39 20 178 197 83
5 -39 20 178 197 83
6 -39 20 178 197 83
7 -39 20 178 197 83
8 -39 20 178 197 83
9 -39 20 178 197 83
10 -39 20 178 197 83
11 -39 20 178 197 83
12 -39 20 178 197 83
13 -39 20 178 197 83
14 -39 20 178 197 83
15 -39 20 178 197 83
16 -39 20 178 197 83
17 -39 20 178 197 83
18 -39 20 178 197 83
19 -39 20 178 197 83
20 -39 20 178 197 83
21 -39 20 178 197 83
22 -39 20 178 197 83
23 -39 20 178 197 83
24 -39 20 178 197 83
25 -39 20 178 197 83
26 -39 20 178 197 83
27 -39 20 178 197 83
28 -39 20 178 197 83
29 -39 20 178 197 83
30 -39 20 178 197 83
31 -39 20 178 197 83
32 -39 20 178 197 83
33 -39 20 178 197 83
34 -39 20 178 197 83
35 -39 20 178 197 83
36 -39 20 178 197 83
37 -39 20 178 197 83
38 -39 20 178 197 83
39 -39 20 178 197 83
40 -39 20 178 197 83
41 -39 20 178 197 83
42 -39 20 178 197 83
43 -39 20 178 197 83
44 -39 20 178 197 83
45 -39 20 178 197 83
46 -39 20 178 197 83
47 -39 20 178 197 83
48 -39 20 178 197 83
-43 -38 20 103 113 88
-42 -38 20 103 113 88
-41 -38 20 103 113 88
-43 -37 20 103 113 88
-42 -37 20 103 113 88
-41 -37 20 103 113 88
-37 -37 20 255 255 255
-43 -36 20 103 113 88
-42 -36 20 103 113 88
-41 -36 20 103 113 88
-48 -39 21 178 197 83
-47 -39 21 178 197 83
-46 -39 21 178 197 83
-45 -39 21 178 197 83
-44 -39 21 178 197 83
-43 -39 21 178 197 83
-42 -39 21 178 197 83
-41 -39 21 178 197 83
-40 -39 21 178 197 83
-39 -39 21 178 197 83
-38 -39 21 178 197 83
-37 -39 21 178 197 83
-36 -39 21 178 197 83
-35 -39 21 178 197 83
-34 -39 21 178 197 83
-33 -39 21 178 197 83
-32 -39 21 178 197 83
-31 -39 21 178 197 83
-30 -39 21 178 197 83
-29 -39 21 178 197 83
-28 -39 21 178 197 83
-27 -39 21 178 197 83
-26 -39 21 178 197 83
-25 -39 21 178 197 83
-24 -39 21 178 197 83
-23 -39 21 178 197 83
-22 -39 21 178 197 83
-21 -39 21 178 197 83
-20 -39 21 178 197 83
-19 -39 21 178 197 83
-18 -39 21 178 197 83
-17 -39 21 178 197 83
-16 -39 21 178 197 83
-15 -39 21 178 197 83
-14 -39 21 178 197 83
-13 -39 21 178 197 83
-12 -39 21 178 197 83
-11 -39 21 178 197 83
-10 -39 21 178 197 83
-9 -39 21 178 197 83
-8 -39 21 178 197 83
-7 -39 21 178 197 83
-6 -39 21 178 197 83
-5 -39 21 178 197 83
-4 -39 21 178 197 83
-3 -39 21 178 197 83
-2 -39 21 178 197 83
-1 -39 21 178 197 83
0 -39 21 178 197 83
1 -39 21 178 197 83
2 -39 21 178 197 83
3 -39 21 178 197 83
4 -39 21 178 197 83
5 -39 21 178 197 83
6 -39 21 178 197 83
7 -39 21 178 197 83
8 -39 21 178 197 83
9 -39 21 178 197 83
10 -39 21 178 197 83
11 -39 21 178 197 83
12 -39 21 178 197 83
13 -39 21 178 197 83
14 -39 21 178 197 83
15 -39 21 178 197 83
16 -39 21 178 197 83
17 -39 21 178 197 83
18 -39 21 178 197 83
19 -39 21 178 197 83
20 -39 21 178 197 83
21 -39 21 178 197 83
22 -39 21 178 197 83
23 -39 21 178 197 83
24 -39 21 178 197 83
25 -39 21 178 197 83
26 -39 21 178 197 83
27 -39 21 178 197 83
28 -39 21 178 197 83
29 -39 21 178 197 83
30 -39 21 178 197 83
31 -39 21 178 197 83
32 -39 21 178 197 83
33 -39 21 178 197 83
34 -39 21 178 197 83
35 -39 21 178 197 83
36 -39 21 178 197 83
37 -39 21 178 197 83
38 -39 21 178 197 83
39 -39 21 178 197 83
40 -39 21 178 197 83
41 -39 21 178 197 83
42 -39 21 178 197 83
43 -39 21 178 197 83
44 -39 21 178 197 83
45 -39 21 178 197 83
46 -39 21 178 197 83
47 -39 21 178 197 83
48 -39 21 178 197 83
-43 -38 21 103 113 88
-42 -38 21 103 113 88
-41 -38 21 103 113 88
-37 -38 21 255 255 255
-26 -38 21 199 194 154
-25 -38 21 199 194 154
-24 -38 21 199 194 154
-23 -38 21 199 194 154
-22 -38 21 199 194 154
-21 -38 21 199 194 154
-20 -38 21 199 194 154
36 -38 21 199 194 154
37 -38 21 199 194 154
38 -38 21 199 194 154
39 -38 21 199 194 154
40 -38 21 199 194 154
41 -38 21 199 194 154
42 -38 21 199 194 154
-43 -37 21 103 113 88
-42 -37 21 103 113 88
-41 -37 21 103 113 88
-38 -37 21 255 255 255
-37 -37 21 255 255 255
-36 -37 21 255 255 255
-26 -37 21 199 194 154
-25 -37 21 199 194 154
-24 -37 21 199 194 154
-23 -37 21 199 194 154
-22 -37 21 199 194 154
-21 -37 21 199 194 154
-20 -37 21 199 194 154
36 -37 21 199 194 154
37 -37 21 199 194 154
38 -37 21 199 194 154
39 -37 21 199 194 154
40 -37 21 199 194 154
41 -37 21 199 194 154
42 -37 21 199 194 154
-43 -36 21 103 113 88
-42 -36 21 103 113 88
-41 -36 21 103 113 88
-26 -36 21 199 194 154
-25 -36 21 199 194 154
-24 -36 21 199 194 154
-23 -36 21 199 194 154
-22 -36 21 199 194 154
-21 -36 21 199 194 154
-20 -36 21 199 194 154
36 -36 21 199 194 154
37 -36 21 199 194 154
38 -36 21 199 194 154
39 -36 21 199 194 154
40 -36 21 199 194 154
41 -36 21 199 194 154
42 -36 21 199 194 154
-26 -35 21 199 194 154
-25 -35 21 199 194 154
-24 -35 21 199 194 154
-23 -35 21 199 194 154
-22 -35 21 199 194 154
-21 -35 21 199 194 154
-20 -35 21 199 194 154
36 -35 21 199 194 154
37 -35 21 199 194 154
38 -35 21 199 194 154
39 -35 21 199 194 154
40 -35 21 199 194 154
41 -35 21 199 194 154
42 -35 21 199 194 154
-26 -34 21 199 194 154
-25 -34 21 199 194 154
-24 -34 21 199 194 154
-23 -34 21 199 194 154
-22 -34 21 199 194 154
-21 -34 21 199 194 154
-20 -34 21 199 194 154
36 -34 21 199 194 154
37 -34 21 199 194 154
38 -34 21 199 194 154
39 -34 21 199 194 154
40 -34 21 199 194 154
41 -34 21 199 194 154
42 -34 21 199 194 154
-26 -33 21 199 194 154
-25 -33 21 199 194 154
-24 -33 21 199 194 154
-23 -33 21 199 194 154
-22 -33 21 199 194 154
-21 -33 21 199 194 154
-20 -33 21 199 194 154
36 -33 21 199 194 154
37 -33 21 199 194 154
38 -33 21 199 194 154
39 -33 21 199 194 154
40 -33 21 199 194 154
41 -33 21 199 194 154
42 -33 21 199 194 154
-26 -32 21 199 194 154
-25 -32 21 199 194 154
-24 -32 21 199 194 154
-23 -32 21 199 194 154
-22 -32 21 199 194 154
-21 -32 21 199 194 154
-20 -32 21 199 194 154
-26 -31 21 199 194 154
-25 -31 21 199 194 154
-24 -31 21 199 194 154
-23 -31 21 199 194 154
-22 -31 21 199 194 154
-21 -31 21 199 194 154
-20 -31 21 199 194 154
-26 -30 21 199 194 154
-25 -30 21 199 194 154
-24 -30 21 199 194 154
-23 -30 21 199 194 154
-22 -30 21 199 194 154
-21 -30 21 199 194 154
-20 -30 21 199 194 154
-26 -29 21 199 194 154
-25 -29 21 199 194 154
-24 -29 21 199 194 154
-23 -29 21 199 194 154
-22 -29 21 199 194 154
-21 -29 21 199 194 154
-20 -29 21 199 194 154
-26 -28 21 199 194 154
-25 -28 21 199 194 154
-24 -28 21 199 194 154
-23 -28 21 199 194 154
-22 -28 21 199 194 154
-21 -28 21 199 194 154
-20 -28 21 199 194 154
-26 -27 21 199 194 154
-25 -27 21 199 194 154
-24 -27 21 199 194 154
-23 -27 21 199 194 154
-22 -27 21 199 194 154
-21 -27 21 199 194 154
-20 -27 21 199 194 154
-26 -26 21 199 194 154
-25 -26 21 199 194 154
-24 -26 21 199 194 154
-23 -26 21 199 194 154
-22 -26 21 199 194 154
-21 -26 21 199 194 154
-20 -26 21 199 194 154
-26 -25 21 199 194 154
-25 -25 21 199 194 154
-24 -25 21 199 194 154
-23 -25 21 199 194 154
-22 -25 21 199 194 154
-21 -25 21 199 194 154
-20 -25 21 199 194 154
-26 -24 21 199 194 154
-25 -24 21 199 194 154
-24 -24 21 199 194 154
-23 -24 21 199 194 154
-22 -24 21 199 194 154
-21 -24 21 199 194 154
-20 -24 21 199 194 154
-26 -23 21 199 194 154
-25 -23 21 199 194 154
-24 -23 21 199 194 154
-23 -23 21 199 194 154
-22 -23 21 199 194 154
-21 -23 21 199 194 154
-20 -23 21 199 194 154
-26 -22 21 199 194 154
-25 -22 21 199 194 154
-24 -22 21 199 194 154
-23 -22 21 199 194 154
-22 -22 21 199 194 154
-21 -22 21 199 194 154
-20 -22 21 199 194 154
-26 -21 21 199 194 154
-25 -21 21 199 194 154
-24 -21 21 199 194 154
-23 -21 21 199 194 154
-22 -21 21 199 194 154
-21 -21 21 199 194 154
-20 -21 21 199 194 154
-26 -20 21 199 194 154
-25 -20 21 199 194 154
-24 -20 21 199 194 154
-23 -20 21 199 194 154
-22 -20 21 199 194 154
-21 -20 21 199 194 154
-20 -20 21 199 194 154
-26 -19 21 199 194 154
-25 -19 21 199 194 154
-24 -19 21 199 194 154
-23 -19 21 199 194 154
-22 -19 21 199 194 154
-21 -19 21 199 194 154
-20 -19 21 199 194 154
-26 -18 21 199 194 154
-25 -18 21 199 194 154
-24 -18 21 199 194 154
-23 -18 21 199 194 154
-22 -18 21 199 194 154
-21 -18 21 199 194 154
-20 -18 21 199 194 154
-48 -39 22 178 197 83
-47 -39 22 178 197 83
-46 -39 22 178 197 83
-45 -39 22 178 197 83
-44 -39 22 178 197 83
-43 -39 22 178 197 83
-42 -39 22 178 197 83
-41 -39 22 178 197 83
-40 -39 22 178 197 83
-39 -39 22 178 197 83
-38 -39 22 178 197 83
-37 -39 22 178 197 83
-36 -39 22 178 197 83
-35 -39 22 178 197 83
-34 -39 22 178 197 83
-33 -39 22 178 197 83
-32 -39 22 178 197 83
-31 -39 22 178 197 83
-30 -39 22 178 197 83
-29 -39 22 178 197 83
-28 -39 22 178 197 83
-27 -39 22 178 197 83
-26 -39 22 178 197 83
-25 -39 22 178 197 83
-24 -39 22 178 197 83
-23 -39 22 178 197 83
-22 -39 22 178 197 83
-21 -39 22 178 197 83
-20 -39 22 178 197 83
-19 -39 22 178 197 83
-18 -39 22 178 197 83
-17 -39 22 178 197 83
-16 -39 22 178 197 83
-15 -39 22 178 197 83
-14 -39 22 178 197 83
-13 -39 22 178 197 83
-12 -39 22 178 197 83
-11 -39 22 178 197 83
-10 -39 22 178 197 83
-9 -39 22 178 197 83
-8 -39 22 178 197 83
-7 -39 22 178 197 83
-6 -39 22 178 197 83
-5 -39 22 178 197 83
-4 -39 22 178 197 83
-3 -39 22 178 197 83
-2 -39 22 178 197 83
-1 -39 22 178 197 83
0 -39 22 178 197 83
1 -39 22 178 197 83
2 -39 22 178 197 83
3 -39 22 178 197 83
4 -39 22 178 197 83
5 -39 22 178 197 83
6 -39 22 178 197 83
7 -39 22 178 197 83
8 -39 22 178 197 83
9 -39 22 178 197 83
10 -39 22 178 197 83
11 -39 22 178 197 83
12 -39 22 178 197 83
13 -39 22 178 197 83
14 -39 22 178 197 83
15 -39 22 178 197 83
16 -39 22 178 197 83
17 -39 22 178 197 83
18 -39 22 178 197 83
19 -39 22 178 197 83
20 -39 22 178 197 83
21 -39 22 178 197 83
22 -39 22 178 197 83
23 -39 22 178 197 83
24 -39 22 178 197 83
25 -39 22 178 197 83
26 -39 22 178 197 83
27 -39 22 178 197 83
28 -39 22 178 197 83
29 -39 22 178 197 83
30 -39 22 178 197 83
31 -39 22 178 197 83
32 -39 22 178 197 83
33 -39 22 178 197 83
34 -39 22 178 197 83
35 -39 22 178 197 83
36 -39 22 178 197 83
37 -39 22 178 197 83
38 -39 22 178 197 83
39 -39 22 178 197 83
40 -39 22 178 197 83
41 -39 22 178 197 83
42 -39 22 178 197 83
43 -39 22 178 197 83
44 -39 22 178 197 83
45 -39 22 178 197 83
46 -39 22 178 197 83
47 -39 22 178 197 83
48 -39 22 178 197 83
-43 -38 22 103 113 88
-42 -38 22 103 113 88
-41 -38 22 103 113 88
-26 -38 22 199 194 154
-25 -38 22 199 194 154
-24 -38 22 199 194 154
-23 -38 22 199 194 154
-22 -38 22 199 194 154
-21 -38 22 199 194 154
-20 -38 22 199 194 154
36 -38 22 199 194 154
37 -38 22 199 194 154
38 -38 22 199 194 154
39 -38 22 199 194 154
40 -38 22 199 194 154
41 -38 22 199 194 154
42 -38 22 199 194 154
-43 -37 22 103 113 88
-42 -37 22 103 113 88
-41 -37 22 103 113 88
-37 -37 22 255 255 255
-26 -37 22 199 194 154
-25 -37 22 199 194 154
-24 -37 22 199 194 154
-23 -37 22 199 194 154
-22 -37 22 199 194 154
-21 -37 22 199 194 154
-20 -37 22 199 194 154
36 -37 22 199 194 154
37 -37 22 199 194 154
38 -37 22 199 194 154
39 -37 22 199 194 154
40 -37 22 199 194 154
41 -37 22 199 194 154
42 -37 22 199 194 154
-43 -36 22 103 113 88
-42 -36 22 103 113 88
-41 -36 22 103 113 88
-26 -36 22 199 194 154
-25 -36 22 199 194 154
-24 -36 22 199 194 154
-23 -36 22 199 194 154
-22 -36 22 199 194 154
-21 -36 22 199 194 154
-20 -36 22 199 194 154
36 -36 22 199 194 154
37 -36 22 199 194 154
38 -36 22 199 194 154
39 -36 22 199 194 154
40 -36 22 199 194 154
41 -36 22 199 194 154
42 -36 22 199 194 154
-26 -35 22 199 194 154
-25 -35 22 199 194 154
-24 -35 22 199 194 154
-23 -35 22 199 194 154
-22 -35 22 199 194 154
-21 -35 22 199 194 154
-20 -35 22 199 194 154
36 -35 22 199 194 154
37 -35 22 199 194 154
38 -35 22 199 194 154
39 -35 22 199 194 154
40 -35 22 199 194 154
41 -35 22 199 194 154
42 -35 22 199 194 154
-26 -34 22 199 194 154
-25 -34 22 199 194 154
-24 -34 22 199 194 154
-23 -34 22 199 194 154
-22 -34 22 199 194 154
-21 -34 22 199 194 154
-20 -34 22 199 194 154
36 -34 22 199 194 154
37 -34 22 199 194 154
38 -34 22 199 194 154
39 -34 22 199 194 154
40 -34 22 199 194 154
41 -34 22 199 194 154
42 -34 22 199 194 154
-26 -33 22 199 194 154
-25 -33 22 199 194 154
-24 -33 22 199 194 154
-23 -33 22 199 194 154
-22 -33 22 199 194 154
-21 -33 22 199 194 154
-20 -33 22 199 194 154
36 -33 22 199 194 154
37 -33 22 199 194 154
38 -33 22 199 194 154
39 -33 22 199 194 154
40 -33 22 199 194 154
41 -33 22 199 194 154
42 -33 22 199 194 154
-26 -32 22 199 194 154
-25 -32 22 199 194 154
-24 -32 22 199 194 154
-23 -32 22 199 194 154
-22 -32 22 199 194 154
-21 -32 22 199 194 154
-20 -32 22 199 194 154
37 -32 22 89 102 54
38 -32 22 89 102 54
39 -32 22 89 102 54
40 -32 22 89 102 54
41 -32 22 89 102 54
-26 -31 22 199 194 154
-25 -31 22 199 194 154
-24 -31 22 199 194 154
-23 -31 22 199 194 154
-22 -31 22 199 194 154
-21 -31 22 199 194 154
-20 -31 22 199 194 154
-26 -30 22 199 194 154
-25 -30 22 199 194 154
-24 -30 22 199 194 154
-23 -30 22 199 194 154
-22 -30 22 199 194 154
-21 -30 22 199 194 154
-20 -30 22 199 194 154
-26 -29 22 199 194 154
-25 -29 22 199 194 154
-24 -29 22 199 194 154
-23 -29 22 199 194 154
-22 -29 22 199 194 154
-21 -29 22 199 194 154
-20 -29 22 199 194 154
-26 -28 22 199 194 154
-25 -28 22 199 194 154
-24 -28 22 199 194 154
-23 -28 22 199 194 154
-22 -28 22 199 194 154
-21 -28 22 199 194 154
-20 -28 22 199 194 154
-26 -27 22 199 194 154
-25 -27 22 199 194 154
-24 -27 22 199 194 154
-23 -27 22 199 194 154
-22 -27 22 199 194 154
-21 -27 22 199 194 154
-20 -27 22 199 194 154
-26 -26 22 199 194 154
-25 -26 22 199 194 154
-24 -26 22 199 194 154
-23 -26 22 199 194 154
-22 -26 22 199 194 154
-21 -26 22 199 194 154
-20 -26 22 199 194 154
-26 -25 22 199 194 154
-25 -25 22 199 194 154
-24 -25 22 199 194 154
-23 -25 22 199 194 154
-22 -25 22 199 194 154
-21 -25 22 199 194 154
-20 -25 22 199 194 154
-26 -24 22 199 194 154
-25 -24 22 199 194 154
-24 -24 22 199 194 154
-23 -24 22 199 194 154
-22 -24 22 199 194 154
-21 -24 22 199 194 154
-20 -24 22 199 194 154
-26 -23 22 199 194 154
-25 -23 22 199 194 154
-24 -23 22 199 194 154
-23 -23 22 199 194 154
-22 -23 22 199 194 154
-21 -23 22 199 194 154
-20 -23 22 199 194 154
-26 -22 22 199 194 154
-25 -22 22 199 194 154
-24 -22 22 199 194 154
-23 -22 22 199 194 154
-22 -22 22 199 194 154
-21 -22 22 199 194 154
-20 -22 22 199 194 154
-26 -21 22 199 194 154
-25 -21 22 199 194 154
-24 -21 22 199 194 154
-23 -21 22 199 194 154
-22 -21 22 199 194 154
-21 -21 22 199 194 154
-20 -21 22 199 194 154
-26 -20 22 199 194 154
-25 -20 22 199 194 154
-24 -20 22 199 194 154
-23 -20 22 199 194 154
-22 -20 22 199 194 154
-21 -20 22 199 194 154
-20 -20 22 199 194 154
-26 -19 22 199 194 154
-25 -19 22 199 194 154
-24 -19 22 199 194 154
-23 -19 22 199 194 154
-22 -19 22 199 194 154
-21 -19 22 199 194 154
-20 -19 22 199 194 154
-26 -18 22 199 194 154
-25 -18 22 199 194 154
-24 -18 22 199 194 154
-23 -18 22 199 194 154
-22 -18 22 199 194 154
-21 -18 22 199 194 154
-20 -18 22 199 194 154
-25 -17 22 89 102 54
-24 -17 22 89 102 54
-23 -17 22 89 102 54
-22 -17 22 89 102 54
-21 -17 22 89 102 54
-48 -39 23 178 197 83
-47 -39 23 178 197 83
-46 -39 23 178 197 83
-45 -39 23 178 197 83
-44 -39 23 178 197 83
-43 -39 23 178 197 83
-42 -39 23 178 197 83
-41 -39 23 178 197 83
-40 -39 23 178 197 83
-39 -39 23 178 197 83
-38 -39 23 178 197 83
-37 -39 23 178 197 83
-36 -39 23 178 197 83
-35 -39 23 178 197 83
-34 -39 23 178 197 83
-33 -39 23 178 197 83
-32 -39 23 178 197 83
-31 -39 23 178 197 83
-30 -39 23 178 197 83
-29 -39 23 178 197 83
-28 -39 23 178 197 83
-27 -39 23 178 197 83
-26 -39 23 178 197 83
-25 -39 23 178 197 83
-24 -39 23 178 197 83
-23 -39 23 178 197 83
-22 -39 23 178 197 83
-21 -39 23 178 197 83
-20 -39 23 178 197 83
-19 -39 23 178 197 83
-18 -39 23 178 197 83
-17 -39 23 178 197 83
-16 -39 23 178 197 83
-15 -39 23 178 197 83
-14 -39 23 178 197 83
-13 -39 23 178 197 83
-12 -39 23 178 197 83
-11 -39 23 178 197 83
-10 -39 23 178 197 83
-9 -39 23 178 197 83
-8 -39 23 178 197 83
-7 -39 23 178 197 83
-6 -39 23 178 197 83
-5 -39 23 178 197 83
-4 -39 23 178 197 83
-3 -39 23 178 197 83
-2 -39 23 178 197 83
-1 -39 23 178 197 83
0 -39 23 178 197 83
1 -39 23 178 197 83
2 -39 23 178 197 83
3 -39 23 178 197 83
4 -39 23 178 197 83
5 -39 23 178 197 83
6 -39 23 178 197 83
7 -39 23 178 197 83
8 -39 23 178 197 83
9 -39 23 178 197 83
10 -39 23 178 197 83
11 -39 23 178 197 83
12 -39 23 178 197 83
13 -39 23 178 197 83
14 -39 23 178 197 83
15 -39 23 178 197 83
16 -39 23 178 197 83
17 -39 23 178 197 83
18 -39 23 178 197 83
19 -39 23 178 197 83
20 -39 23 178 197 83
21 -39 23 178 197 83
22 -39 23 178 197 83
23 -39 23 178 197 83
24 -39 23 178 197 83
25 -39 23 178 197 83
26 -39 23 178 197 83
27 -39 23 178 197 83
28 -39 23 178 197 83
29 -39 23 178 197 83
30 -39 23 178 197 83
31 -39 23 178 197 83
32 -39 23 178 197 83
33 -39 23 178 197 83
34 -39 23 178 197 83
35 -39 23 178 197 83
36 -39 23 178 197 83
37 -39 23 178 197 83
38 -39 23 178 197 83
39 -39 23 178 197 83
40 -39 23 178 197 83
41 -39 23 178 197 83
42 -39 23 178 197 83
43 -39 23 178 197 83
44 -39 23 178 197 83
45 -39 23 178 197 83
46 -39 23 178 197 83
47 -39 23 178 197 83
48 -39 23 178 197 83
-26 -38 23 199 194 154
-25 -38 23 199 194 154
-24 -38 23 199 194 154
-23 -38 23 199 194 154
-22 -38 23 199 194 154
-21 -38 23 199 194 154
-20 -38 23 199 194 154
36 -38 23 199 194 154
37 -38 23 199 194 154
38 -38 23 199 194 154
39 -38 23 199 194 154
40 -38 23 199 194 154
41 -38 23 199 194 154
42 -38 23 199 194 154
-26 -37 23 199 194 154
-25 -37 23 199 194 154
-24 -37 23 199 194 154
-23 -37 23 199 194 154
-22 -37 23 199 194 154
-21 -37 23 199 194 154
-20 -37 23 199 194 154
36 -37 23 199 194 154
37 -37 23 199 194 154
38 -37 23 199 194 154
39 -37 23 199 194 154
40 -37 23 199 194 154
41 -37 23 199 194 154
42 -37 23 199 194 154
-26 -36 23 199 194 154
-25 -36 23 199 194 154
-24 -36 23 199 194 154
-23 -36 23 199 194 154
-22 -36 23 199 194 154
-21 -36 23 199 194 154
-20 -36 23 199 194 154
36 -36 23 199 194 154
37 -36 23 199 194 154
38 -36 23 199 194 154
39 -36 23 199 194 154
40 -36 23 199 194 154
41 -36 23 199 194 154
42 -36 23 199 194 154
-26 -35 23 199 194 154
-25 -35 23 199 194 154
-24 -35 23 199 194 154
-23 -35 23 199 194 154
-22 -35 23 199 194 154
-21 -35 23 199 194 154
-20 -35 23 199 194 154
36 -35 23 199 194 154
37 -35 23 199 194 154
38 -35 23 199 194 154
39 -35 23 199 194 154
40 -35 23 199 194 154
41 -35 23 199 194 154
42 -35 23 199 194 154
-26 -34 23 199 194 154
-25 -34 23 199 194 154
-24 -34 23 199 194 154
-23 -34 23 199 194 154
-22 -34 23 199 194 154
-21 -34 23 199 194 154
-20 -34 23 199 194 154
36 -34 23 199 194 154
37 -34 23 199 194 154
38 -34 23 199 194 154
39 -34 23 199 194 154
40 -34 23 199 194 154
41 -34 23 199 194 154
42 -34 23 199 194 154
-26 -33 23 199 194 154
-25 -33 23 199 194 154
-24 -33 23 199 194 154
-23 -33 23 199 194 154
-22 -33 23 199 194 154
-21 -33 23 199 194 154
-20 -33 23 199 194 154
36 -33 23 199 194 154
37 -33 23 199 194 154
38 -33 23 199 194 154
39 -33 23 199 194 154
40 -33 23 199 194 154
41 -33 23 199 194 154
42 -33 23 199 194 154
-26 -32 23 199 194 154
-25 -32 23 199 194 154
-24 -32 23 199 194 154
-23 -32 23 199 194 154
-22 -32 23 199 194 154
-21 -32 23 199 194 154
-20 -32 23 199 194 154
37 -32 23 89 102 54
38 -32 23 248 168 51
39 -32 23 248 168 51
40 -32 23 248 168 51
41 -32 23 89 102 54
-26 -31 23 199 194 154
-25 -31 23 199 194 154
-24 -31 23 199 194 154
-23 -31 23 199 194 154
-22 -31 23 199 194 154
-21 -31 23 199 194 154
-20 -31 23 199 194 154
-26 -30 23 199 194 154
-25 -30 23 199 194 154
-24 -30 23 199 194 154
-23 -30 23 199 194 154
-22 -30 23 199 194 154
-21 -30 23 199 194 154
-20 -30 23 199 194 154
-26 -29 23 199 194 154
-25 -29 23 199 194 154
-24 -29 23 199 194 154
-23 -29 23 199 194 154
-22 -29 23 199 194 154
-21 -29 23 199 194 154
-20 -29 23 199 194 154
-26 -28 23 199 194 154
-25 -28 23 199 194 154
-24 -28 23 199 194 154
-23 -28 23 199 194 154
-22 -28 23 199 194 154
-21 -28 23 199 194 154
-20 -28 23 199 194 154
-26 -27 23 199 194 154
-25 -27 23 199 194 154
-24 -27 23 199 194 154
-23 -27 23 199 194 154
-22 -27 23 199 194 154
-21 -27 23 199 194 154
-20 -27 23 199 194 154
-26 -26 23 199 194 154
-25 -26 23 199 194 154
-24 -26 23 199 194 154
-23 -26 23 199 194 154
-22 -26 23 199 194 154
-21 -26 23 199 194 154
-20 -26 23 199 194 154
-26 -25 23 199 194 154
-25 -25 23 199 194 154
-24 -25 23 199 194 154
-23 -25 23 199 194 154
-22 -25 23 199 194 154
-21 -25 23 199 194 154
-20 -25 23 199 194 154
-26 -24 23 199 194 154
-25 -24 23 199 194 154
-24 -24 23 199 194 154
-23 -24 23 199 194 154
-22 -24 23 199 194 154
-21 -24 23 199 194 154
-20 -24 23 199 194 154
-26 -23 23 199 194 154
-25 -23 23 199 194 154
-24 -23 23 199 194 154
-23 -23 23 199 194 154
-22 -23 23 199 194 154
-21 -23 23 199 194 154
-20 -23 23 199 194 154
-26 -22 23 199 194 154
-25 -22 23 199 194 154
-24 -22 23 199 194 154
-23 -22 23 199 194 154
-22 -22 23 199 194 154
-21 -22 23 199 194 154
-20 -22 23 199 194 154
-26 -21 23 199 194 154
-25 -21 23 199 194 154
-24 -21 23 199 194 154
-23 -21 23 199 194 154
-22 -21 23 199 194 154
-21 -21 23 199 194 154
-20 -21 23 199 194 154
-26 -20 23 199 194 154
-25 -20 23 199 194 154
-24 -20 23 199 194 154
-23 -20 23 199 194 154
-22 -20 23 199 194 154
-21 -20 23 199 194 154
-20 -20 23 199 194 154
-26 -19 23 199 194 154
-25 -19 23 199 194 154
-24 -19 23 199 194 154
-23 -19 23 199 194 154
-22 -19 23 199 194 154
-21 -19 23 199 194 154
-20 -19 23 199 194 154
-26 -18 23 199 194 154
-25 -18 23 199 194 154
-24 -18 23 199 194 154
-23 -18 23 199 194 154
-22 -18 23 199 194 154
-21 -18 23 199 194 154
-20 -18 23 199 194 154
-25 -17 23 89 102 54
-24 -17 23 248 168 51
-23 -17 23 248 168 51
-22 -17 23 248 168 51
-21 -17 23 89 102 54
-48 -39 24 178 197 83
-47 -39 24 178 197 83
-46 -39 24 178 197 83
-45 -39 24 178 197 83
-44 -39 24 178 197 83
-43 -39 24 178 197 83
-42 -39 24 178 197 83
-41 -39 24 178 197 83
-40 -39 24 178 197 83
-39 -39 24 178 197 83
-38 -39 24 178 197 83
-37 -39 24 178 197 83
-36 -39 24 178 197 83
-35 -39 24 178 197 83
-34 -39 24 178 197 83
-33 -39 24 178 197 83
-32 -39 24 178 197 83
-31 -39 24 178 197 83
-30 -39 24 178 197 83
-29 -39 24 178 197 83
-28 -39 24 178 197 83
-27 -39 24 178 197 83
-26 -39 24 178 197 83
-25 -39 24 178 197 83
-24 -39 24 178 197 83
-23 -39 24 178 197 83
-22 -39 24 178 197 83
-21 -39 24 178 197 83
-20 -39 24 178 197 83
-19 -39 24 178 197 83
-18 -39 24 178 197 83
-17 -39 24 178 197 83
-16 -39 24 178 197 83
-15 -39 24 178 197 83
-14 -39 24 178 197 83
-13 -39 24 178 197 83
-12 -39 24 178 197 83
-11 -39 24 178 197 83
-10 -39 24 178 197 83
-9 -39 24 178 197 83
-8 -39 24 178 197 83
-7 -39 24 178 197 83
-6 -39 24 178 197 83
-5 -39 24 178 197 83
-4 -39 24 178 197 83
-3 -39 24 178 197 83
-2 -39 24 178 197 83
-1 -39 24 178 197 83
0 -39 24 178 197 83
1 -39 24 178 197 83
2 -39 24 178 197 83
3 -39 24 178 197 83
4 -39 24 178 197 83
5 -39 24 178 197 83
6 -39 24 178 197 83
7 -39 24 178 197 83
8 -39 24 178 197 83
9 -39 24 178 197 83
10 -39 24 178 197 83
11 -39 24 178 197 83
12 -39 24 178 197 83
13 -39 24 178 197 83
14 -39 24 178 197 83
15 -39 24 178 197 83
16 -39 24 178 197 83
17 -39 24 178 197 83
18 -39 24 178 197 83
19 -39 24 178 197 83
20 -39 24 178 197 83
21 -39 24 178 197 83
22 -39 24 178 197 83
23 -39 24 178 197 83
24 -39 24 178 197 83
25 -39 24 178 197 83
26 -39 24 178 197 83
27 -39 24 178 197 83
28 -39 24 178 197 83
29 -39 24 178 197 83
30 -39 24 178 197 83
31 -39 24 178 197 83
32 -39 24 178 197 83
33 -39 24 178 197 83
34 -39 24 178 197 83
35 -39 24 178 197 83
36 -39 24 178 197 83
37 -39 24 178 197 83
38 -39 24 178 197 83
39 -39 24 178 197 83
40 -39 24 178 197 83
41 -39 24 178 197 83
42 -39 24 178 197 83
43 -39 24 178 197 83
44 -39 24 178 197 83
45 -39 24 178 197 83
46 -39 24 178 197 83
47 -39 24 178 197 83
48 -39 24 178 197 83
-26 -38 24 199 194 154
-25 -38 24 199 194 154
-24 -38 24 199 194 154
-23 -38 24 199 194 154
-22 -38 24 199 194 154
-21 -38 24 199 194 154
-20 -38 24 199 194 154
36 -38 24 199 194 154
37 -38 24 199 194 154
38 -38 24 199 194 154
39 -38 24 199 194 154
40 -38 24 199 194 154
41 -38 24 199 194 154
42 -38 24 199 194 154
-26 -37 24 199 194 154
-25 -37 24 199 194 154
-24 -37 24 199 194 154
-23 -37 24 199 194 154
-22 -37 24 199 194 154
-21 -37 24 199 194 154
-20 -37 24 199 194 154
36 -37 24 199 194 154
37 -37 24 199 194 154
38 -37 24 199 194 154
39 -37 24 199 194 154
40 -37 24 199 194 154
41 -37 24 199 194 154
42 -37 24 199 194 154
-26 -36 24 199 194 154
-25 -36 24 199 194 154
-24 -36 24 199 194 154
-23 -36 24 199 194 154
-22 -36 24 199 194 154
-21 -36 24 199 194 154
-20 -36 24 199 194 154
36 -36 24 199 194 154
37 -36 24 199 194 154
38 -36 24 199 194 154
39 -36 24 199 194 154
40 -36 24 199 194 154
41 -36 24 199 194 154
42 -36 24 199 194 154
-26 -35 24 199 194 154
-25 -35 24 199 194 154
-24 -35 24 199 194 154
-23 -35 24 199 194 154
-22 -35 24 199 194 154
-21 -35 24 199 194 154
-20 -35 24 199 194 154
36 -35 24 199 194 154
37 -35 24 199 194 154
38 -35 24 199 194 154
39 -35 24 199 194 154
40 -35 24 199 194 154
41 -35 24 199 194 154
42 -35 24 199 194 154
-26 -34 24 199 194 154
-25 -34 24 199 194 154
-24 -34 24 199 194 154
-23 -34 24 199 194 154
-22 -34 24 199 194 154
-21 -34 24 199 194 154
-20 -34 24 199 194 154
36 -34 24 199 194 154
37 -34 24 199 194 154
38 -34 24 199 194 154
39 -34 24 199 194 154
40 -34 24 199 194 154
41 -34 24 199 194 154
42 -34 24 199 194 154
-26 -33 24 199 194 154
-25 -33 24 199 194 154
-24 -33 24 199 194 154
-23 -33 24 199 194 154
-22 -33 24 199 194 154
-21 -33 24 199 194 154
-20 -33 24 199 194 154
36 -33 24 199 194 154
37 -33 24 199 194 154
38 -33 24 199 194 154
39 -33 24 199 194 154
40 -33 24 199 194 154
41 -33 24 199 194 154
42 -33 24 199 194 154
-26 -32 24 199 194 154
-25 -32 24 199 194 154
-24 -32 24 199 194 154
-23 -32 24 199 194 154
-22 -32 24 199 194 154
-21 -32 24 199 194 154
-20 -32 24 199 194 154
37 -32 24 89 102 54
38 -32 24 248 168 51
39 -32 24 248 168 51
40 -32 24 248 168 51
41 -32 24 89 102 54
-26 -31 24 199 194 154
-25 -31 24 199 194 154
-24 -31 24 199 194 154
-23 -31 24 199 194 154
-22 -31 24 199 194 154
-21 -31 24 199 194 154
-20 -31 24 199 194 154
-26 -30 24 199 194 154
-25 -30 24 199 194 154
-24 -30 24 199 194 154
-23 -30 24 199 194 154
-22 -30 24 199 194 154
-21 -30 24 199 194 154
-20 -30 24 199 194 154
-26 -29 24 199 194 154
-25 -29 24 199 194 154
-24 -29 24 199 194 154
-23 -29 24 199 194 154
-22 -29 24 199 194 154
-21 -29 24 199 194 154
-20 -29 24 199 194 154
-26 -28 24 199 194 154
-25 -28 24 199 194 154
-24 -28 24 199 194 154
-23 -28 24 199 194 154
-22 -28 24 199 194 154
-21 -28 24 199 194 154
